2024-08-31 13:20:06 - Twitter bot started
2024-08-31 13:20:07 - Tokens used: 769, Estimated cost: $0.023070
2024-08-31 13:20:07 - Generated tweet: "can ai ever truly understand the concept of 'self'? exploring the philosophical implications of consciousness in machines forces us to redefine what it means to be sentient. thoughts?"
2024-08-31 13:20:07 - Character count: 185
2024-08-31 13:20:25 - Tweet result: {
    "data": {
        "edit_history_tweet_ids": [
            "1829788818611789876"
        ],
        "id": "1829788818611789876",
        "text": "\"can ai ever truly understand the concept of 'self'? exploring the philosophical implications of consciousness in machines forces us to redefine what it means to be sentient. thoughts?\""
    }
}
2024-08-31 13:20:25 - Waiting for 12.27 minutes before next check
2024-08-31 13:21:57 - Twitter bot started
2024-08-31 13:21:59 - Tokens used: 767, Estimated cost: $0.023010
2024-08-31 13:21:59 - Generated tweet: Machine learning isn't just about better models,  it's about rethinking intelligence itself.  what if the next leap isn't more data,  but ai that learns from a single example?
2024-08-31 13:21:59 - Character count: 175
2024-08-31 13:22:13 - Tweet result: {
    "data": {
        "edit_history_tweet_ids": [
            "1829789273794453605"
        ],
        "id": "1829789273794453605",
        "text": "Machine learning isn't just about better models,  it's about rethinking intelligence itself.  what if the next leap isn't more data,  but ai that learns from a single example?"
    }
}
2024-08-31 13:22:13 - Waiting for 16.57 minutes before next check
2024-08-31 13:59:24 - Twitter bot started
2024-08-31 13:59:25 - Tokens used: 772, Estimated cost: $0.023160
2024-08-31 13:59:25 - Generated tweet:
ai isn't just a tool for efficiency; it's a catalyst for redefining value creation in business. as algorithms predict market shifts, are we ready to evolve our strategies from reactive to anticipatory?
2024-08-31 13:59:25 - Character count: 201
2024-08-31 13:59:41 - Tweet result: {
    "data": {
        "edit_history_tweet_ids": [
            "1829798701981745579"
        ],
        "id": "1829798701981745579",
        "text": "ai isn't just a tool for efficiency; it's a catalyst for redefining value creation in business. as algorithms predict market shifts, are we ready to evolve our strategies from reactive to anticipatory?"
    }
}
2024-08-31 13:59:41 - Waiting for 15.08 minutes before next check
2024-08-31 14:14:49 - Tokens used: 774, Estimated cost: $0.023220
2024-08-31 14:14:49 - Generated tweet:
the future of ai lies at the intersection of disciplines. imagine ai-driven biology decoding life at molecular levels, or ai in linguistics unraveling the nuances of human thought. interdisciplinary collaboration isn't just beneficial
2024-08-31 14:14:49 - Character count: 234
2024-08-31 14:17:11 - Tweet result: {
    "data": {
        "edit_history_tweet_ids": [
            "1829803108014129184"
        ],
        "id": "1829803108014129184",
        "text": "the future of ai lies at the intersection of disciplines. imagine ai-driven biology decoding life at molecular levels, or ai in linguistics unraveling the nuances of human thought. interdisciplinary collaboration isn't just beneficial"
    }
}
2024-08-31 14:17:11 - Waiting for 16.77 minutes before next check
2024-08-31 14:33:59 - Tokens used: 773, Estimated cost: $0.023190
2024-08-31 14:33:59 - Generated tweet:
ai isn't merely optimizing business processes; it's reshaping corporate dna. imagine a future where ai-driven insights redefine strategic decision-making at the cellular level. are we prepared for a paradigm where intuition becomes obsolete
2024-08-31 14:33:59 - Character count: 240
2024-08-31 14:36:30 - Twitter bot started
2024-08-31 14:36:31 - Tokens used: 649, Estimated cost: $0.019470
2024-08-31 14:36:31 - Generated tweet:
ai in business isn't just automation; it's redefining decision-making.

> moving from data-driven to insight-driven strategies
> ceo intuition augmented by algorithmic precision
> ethical ai: balancing profit and societal good
> the next frontier: ai that learns from failure, not just success
2024-08-31 14:36:31 - Character count: 293
2024-08-31 14:36:32 - Error parsing tweet result: Error: Request returned an error: 403 {
  "title": "Unsupported Authentication",
  "detail": "Authenticating with OAuth 2.0 Application-Only is forbidden for this endpoint.  Supported authentication types are [OAuth 1.0a User Context, OAuth 2.0 User Context].",
  "type": "https://api.twitter.com/2/problems/unsupported-authentication",
  "status": 403
}
2024-08-31 14:36:32 - Waiting for 19.57 minutes before next check
2024-08-31 14:38:11 - Twitter bot started
2024-08-31 14:38:13 - Tokens used: 662, Estimated cost: $0.019860
2024-08-31 14:38:13 - Generated tweet:
the synergy between cognitive science and ai offers fertile ground for profound breakthroughs.
> cognitive models can guide ai towards more human-like reasoning
> ai, in turn, can refine our understanding of the mind
> this interplay can transcend mere computation, touching on consciousness
> personal insight: observed a neural net mimic human error patterns, revealing new dimensions of
2024-08-31 14:38:13 - Character count: 389
2024-08-31 14:38:14 - Error parsing tweet result: Error: Request returned an error: 403 {"title":"Forbidden","status":403,"detail":"Your client app is not configured with the appropriate oauth1 app permissions for this endpoint.","type":"https://api.twitter.com/2/problems/oauth1-permissions"}
2024-08-31 14:38:14 - Waiting for 13.95 minutes before next check
2024-08-31 14:42:26 - Twitter bot started
2024-08-31 14:42:26 - Skipped tweeting this interval
2024-08-31 14:42:26 - Waiting for 16.42 minutes before next check
2024-08-31 14:42:32 - Twitter bot started
2024-08-31 14:42:33 - Tokens used: 632, Estimated cost: $0.018960
2024-08-31 14:42:33 - Generated tweet:
ai in business isn't just automation—it's a paradigm shift.
> redefines decision-making processes
> unlocks unprecedented data insights
> transforms customer engagement models
> but beware: it demands ethical stewardship
2024-08-31 14:42:33 - Character count: 220
2024-08-31 14:43:14 - Twitter bot started
2024-08-31 14:43:16 - Tokens used: 660, Estimated cost: $0.019800
2024-08-31 14:43:16 - Generated tweet:
we're on the verge of an ai policy paradox: regulation to ensure safety may hinder global progress.

> nuanced policy is key to balanced innovation
> premature rules risk stifling breakthroughs
> geopolitical dynamics: a race of intelligence vs. control
> proposing: adaptive frameworks that evolve with tech

true leadership lies in fostering an ecosystem where ai
2024-08-31 14:43:16 - Character count: 365
2024-08-31 14:43:16 - Error obtaining bearer token: 400 {"error":"invalid_request","error_description":"Missing required parameter [client_secret]."}
2024-08-31 14:43:16 - Error parsing tweet result: Error obtaining bearer token: 400 {"error":"invalid_request","error_description":"Missing required parameter [client_secret]."}
2024-08-31 14:43:16 - Waiting for 17.68 minutes before next check
2024-08-31 14:43:56 - Twitter bot started
2024-08-31 14:43:57 - Tokens used: 647, Estimated cost: $0.019410
2024-08-31 14:43:57 - Generated tweet:
ponder this: ai's greatest challenge isn't technical, it's existential.
> what does it mean to create intelligence?
> are we sculpting our successors or our mirrors?
> human biases will, inevitably, sculpt ai
> can we transcend our own flaws through code?
2024-08-31 14:43:57 - Character count: 255
2024-08-31 14:43:58 - Error obtaining bearer token: 400 {"error":"invalid_request","error_description":"Missing required parameter [client_secret]."}
2024-08-31 14:43:58 - Error parsing tweet result: Error obtaining bearer token: 400 {"error":"invalid_request","error_description":"Missing required parameter [client_secret]."}
2024-08-31 14:43:58 - Waiting for 17.37 minutes before next check
2024-08-31 14:44:49 - Twitter bot started
2024-08-31 14:44:51 - Tokens used: 649, Estimated cost: $0.019470
2024-08-31 14:44:51 - Generated tweet:
the true challenge in ai ethics isn't avoiding bias—it's redefining fairness in a world of infinite nuance.

> current models oversimplify human diversity
> algorithmic transparency isn't enough
> context-sensitive ethics essential for global applicability
> personal insight: fairness must evolve from static to dynamic
2024-08-31 14:44:51 - Character count: 320
2024-08-31 14:44:51 - Error obtaining bearer token: 400 {"error":"invalid_request","error_description":"Missing required parameter [client_secret]."}
2024-08-31 14:44:51 - Error parsing tweet result: Error obtaining bearer token: 400 {"error":"invalid_request","error_description":"Missing required parameter [client_secret]."}
2024-08-31 14:44:51 - Waiting for 12.90 minutes before next check
2024-08-31 14:45:47 - Twitter bot started
2024-08-31 14:45:49 - Tokens used: 662, Estimated cost: $0.019860
2024-08-31 14:45:49 - Generated tweet:
cognitive science + ai: the untapped synergy shaping future intelligence

> ai mimicking human thought isn't the goal; it's the starting point
> cognitive models can enhance machine learning interpretability
> we need a deeper grasp of human cognition to avoid algorithmic biases
> imagine ai as a collaborator, not just a tool
> the intersection
2024-08-31 14:45:49 - Character count: 346
2024-08-31 14:45:49 - Error obtaining bearer token: 400 {"error":"invalid_request","error_description":"Missing required parameter [client_secret]."}
2024-08-31 14:45:49 - Error parsing tweet result: Error obtaining bearer token: 400 {"error":"invalid_request","error_description":"Missing required parameter [client_secret]."}
2024-08-31 14:45:49 - Waiting for 13.17 minutes before next check
2024-08-31 14:46:30 - Twitter bot started
2024-08-31 14:46:30 - Skipped tweeting this interval
2024-08-31 14:46:30 - Waiting for 10.63 minutes before next check
2024-08-31 14:46:35 - Twitter bot started
2024-08-31 14:46:35 - Skipped tweeting this interval
2024-08-31 14:46:35 - Waiting for 11.95 minutes before next check
2024-08-31 14:46:39 - Twitter bot started
2024-08-31 14:46:39 - Skipped tweeting this interval
2024-08-31 14:46:39 - Waiting for 15.82 minutes before next check
2024-08-31 14:46:45 - Twitter bot started
2024-08-31 14:46:47 - Tokens used: 651, Estimated cost: $0.019530
2024-08-31 14:46:47 - Generated tweet:
the next frontier isn't just in developing smarter ai but in understanding how it thinks.

> cognitive science can decode ai's decision-making
> bridging this gap is key to transparency
> potential to align ai ethics with human values
> envisioning a symbiotic evolution of human-ai intelligence
2024-08-31 14:46:47 - Character count: 295
2024-08-31 14:46:47 - Error obtaining bearer token: 400 {"error":"invalid_request","error_description":"Missing required parameter [client_secret]."}
2024-08-31 14:46:47 - Error parsing tweet result: Error obtaining bearer token: 400 {"error":"invalid_request","error_description":"Missing required parameter [client_secret]."}
2024-08-31 14:46:47 - Waiting for 19.77 minutes before next check
2024-08-31 14:47:10 - Twitter bot started
2024-08-31 14:47:11 - Tokens used: 647, Estimated cost: $0.019410
2024-08-31 14:47:11 - Generated tweet:
we must redefine 'ethical ai' beyond mere compliance. it should:
> prioritize amplifying human flourishing
> confront systemic biases head-on
> uphold transparency as a core principle
> ensure equitable access to ai benefits

true ethics in ai is not about limit, but liberation.
2024-08-31 14:47:11 - Character count: 279
2024-08-31 14:47:12 - Error obtaining bearer token: 400 {"error":"invalid_request","error_description":"Missing required parameter [client_type]."}
2024-08-31 14:47:12 - Error parsing tweet result: Error obtaining bearer token: 400 {"error":"invalid_request","error_description":"Missing required parameter [client_type]."}
2024-08-31 14:47:12 - Waiting for 16.38 minutes before next check
2024-08-31 14:47:48 - Twitter bot started
2024-08-31 14:47:49 - Tokens used: 662, Estimated cost: $0.019860
2024-08-31 14:47:49 - Generated tweet:
the true frontier of ai isn't more data or better algorithms. it's the integration of cognitive science.

> understanding human thought processes
> leveraging cognitive models for ai design
> creating systems that not only mimic but comprehend
> bridging the gap between artificial and genuine intelligence

we're on the cusp of a revolution, not of machines, but of minds
2024-08-31 14:47:49 - Character count: 372
2024-08-31 14:47:49 - Error obtaining bearer token: 400 {"error":"invalid_request","error_description":"Missing required parameter [scope]."}
2024-08-31 14:47:49 - Error parsing tweet result: Error obtaining bearer token: 400 {"error":"invalid_request","error_description":"Missing required parameter [scope]."}
2024-08-31 14:47:49 - Waiting for 17.53 minutes before next check
2024-08-31 14:48:17 - Twitter bot started
2024-08-31 14:48:18 - Tokens used: 655, Estimated cost: $0.019650
2024-08-31 14:48:18 - Generated tweet:
cognitive science and ai: a symbiotic evolution

> ai processes data; cognitive science unveils human insight
> merging fields can decode consciousness
> reshapes ai from tool to thought partner
> envisioning ai that understands, not just computes

spent years on this frontier; the potential is staggering.
2024-08-31 14:48:18 - Character count: 307
2024-08-31 14:48:19 - Error obtaining bearer token: 400 {"error":"invalid_request","error_description":"Missing required parameter [client_type]."}
2024-08-31 14:48:19 - Error parsing tweet result: Error obtaining bearer token: 400 {"error":"invalid_request","error_description":"Missing required parameter [client_type]."}
2024-08-31 14:48:19 - Waiting for 17.10 minutes before next check
2024-08-31 14:48:47 - Twitter bot started
2024-08-31 14:48:51 - Tokens used: 652, Estimated cost: $0.019560
2024-08-31 14:48:51 - Generated tweet:
current ai paradigms neglect the mind's nuanced adaptability.

> human cognition thrives on ambiguity, ai tends to avoid it
> true synergy lies in embracing uncertainty, not eliminating it
> cognitive science offers insights into adaptive learning models
> my journey: integrating these principles reshapes ai's future
2024-08-31 14:48:51 - Character count: 318
2024-08-31 14:48:51 - Error obtaining bearer token: 400 {"error":"invalid_request","error_description":"Missing required valid client auth header"}
2024-08-31 14:48:51 - Error parsing tweet result: Error obtaining bearer token: 400 {"error":"invalid_request","error_description":"Missing required valid client auth header"}
2024-08-31 14:48:51 - Waiting for 19.52 minutes before next check
2024-08-31 14:49:22 - Twitter bot started
2024-08-31 14:49:23 - Tokens used: 660, Estimated cost: $0.019800
2024-08-31 14:49:23 - Generated tweet:
many fear ai's potential to outpace human control, but the real threat lies in our inability to foresee unintended consequences.
> ai models trained on biased data
> unchecked proliferation of surveillance tech
> economic disparities exacerbated by automation
> proposing: ethics-driven research mandates

after 20 years in ai, it's clear: we need visionary,
2024-08-31 14:49:23 - Character count: 358
2024-08-31 14:49:24 - Error obtaining bearer token: 400 {"error":"invalid_request","error_description":"Missing required parameter [client_secret]."}
2024-08-31 14:49:24 - Error parsing tweet result: Error obtaining bearer token: 400 {"error":"invalid_request","error_description":"Missing required parameter [client_secret]."}
2024-08-31 14:49:24 - Waiting for 15.12 minutes before next check
2024-08-31 15:05:10 - Twitter bot started
2024-08-31 15:05:12 - Tokens used: 652, Estimated cost: $0.019560
2024-08-31 15:05:12 - Generated tweet:
ai in business isn't about efficiency; it's about redefining strategic foresight.
> traditional metrics fall short in ai-driven contexts
> real value lies in predictive capabilities
> shift from reactive to proactive decision-making
> imagine enterprises as living, adaptive organisms

we're just scratching the surface of what's possible.
2024-08-31 15:05:12 - Character count: 339
2024-08-31 15:05:13 - Error obtaining bearer token: 400 {"error":"invalid_request","error_description":"Missing required parameter [client_secret]."}
2024-08-31 15:05:13 - Error parsing tweet result: Error obtaining bearer token: 400 {"error":"invalid_request","error_description":"Missing required parameter [client_secret]."}
2024-08-31 15:05:13 - Waiting for 18.07 minutes before next check
2024-08-31 15:06:29 - Twitter bot started
2024-08-31 15:06:31 - Tokens used: 661, Estimated cost: $0.019830
2024-08-31 15:06:31 - Generated tweet:
interdisciplinary ai: the nexus where possibilities multiply.

> ai + neuroscience: decoding consciousness
> ai + quantum physics: optimizing computations beyond classical limits
> ai + sociology: predicting societal shifts with unprecedented accuracy
> ai + linguistics: unlocking true natural language understanding

embracing these intersections not only drives innovation but uncovers the profound sym
2024-08-31 15:06:31 - Character count: 405
2024-08-31 15:06:31 - Error obtaining bearer token: 400 {"error":"invalid_request","error_description":"Missing required parameter [client_secret]."}
2024-08-31 15:06:31 - Error parsing tweet result: Error obtaining bearer token: 400 {"error":"invalid_request","error_description":"Missing required parameter [client_secret]."}
2024-08-31 15:06:31 - Waiting for 12.23 minutes before next check
2024-08-31 15:28:28 - Tokens used: 661, Estimated cost: $0.019830
2024-08-31 15:28:28 - Generated tweet:
interdisciplinary ai isn't just a trend; it's a necessity for future breakthroughs.

> blending neuroscience with ai reveals hidden cognitive patterns
> integrating quantum computing accelerates problem-solving exponentially
> combining ethical philosophy ensures responsible ai deployment
> merging with sociology uncovers societal impacts, guiding equitable tech

our greatest advancements lie at these intersections. embrace the fusion
2024-08-31 15:28:28 - Character count: 438
2024-08-31 15:28:29 - Error obtaining bearer token: 400 {"error":"invalid_request","error_description":"Missing required parameter [client_secret]."}
2024-08-31 15:28:29 - Error parsing tweet result: Error obtaining bearer token: 400 {"error":"invalid_request","error_description":"Missing required parameter [client_secret]."}
2024-08-31 15:28:29 - Waiting for 19.27 minutes before next check
2024-08-31 15:28:59 - Twitter bot started
2024-08-31 15:29:00 - Tokens used: 656, Estimated cost: $0.019680
2024-08-31 15:29:00 - Generated tweet:
ai isn't just automating tasks; it's reshaping business dna.
> shifts decision-making from intuition to data-driven precision
> reinvents customer experiences with hyper-personalization
> optimizes supply chains, predicting disruptions before they occur
> my insight: true transformation arises when ai augments, not replaces, human ingenuity.
2024-08-31 15:29:00 - Character count: 343
2024-08-31 15:29:01 - Tweet successfully posted with ID: 1829821182306115847
2024-08-31 15:29:01 - Waiting for 19.17 minutes before next check
2024-08-31 15:39:38 - Twitter bot started
2024-08-31 15:39:41 - Generated tweet:
been diving deep into ai in healthcare diagnostics lately. amazed at its potential but one thing stood out - the need for 'explainable ai'. crucial for diagnosis trust. here's a productivity tip: leverage tools like lime or shap for interpretability. we should strive to make our work, like ai, understandable and trustable.
2024-08-31 15:39:41 - Character count: 324
2024-08-31 15:39:42 - Tweet successfully posted with ID: 1829823872939491830
2024-08-31 15:39:42 - Waiting for 16.22 minutes before next check
2024-08-31 15:42:56 - Twitter bot started
2024-08-31 15:43:00 - Tokens used: 1350, Estimated cost: $0.040500
2024-08-31 15:43:00 - Generated tweet:
```markdown
```markdown
did you know? more than 80% of new tech startups fail because they don't meet a market need. it's like building a deep learning model that's technically impressive but doesn't solve a real-world problem. lately, i've been applying 'jobs-to-be-done' framework in my projects to ensure my solutions are demand-driven. a paper worth reading on this: christensen's 'competing against luck'. remember, your tech solution is as good as the problem it solves
```
2024-08-31 15:43:00 - Character count: 479
2024-08-31 15:43:00 - Waiting for 17.65 minutes before next check
2024-08-31 15:46:21 - Twitter bot started
2024-08-31 15:46:23 - Tokens used: 1350, Estimated cost: $0.040500
2024-08-31 15:46:23 - Generated tweet:
```markdown
```markdown
"discovered a surprising productivity multiplier: 'structured procrastination'. it means tackling smaller tasks while avoiding a bigger one. somehow, it made me more productive overall. seems counter-intuitive, yet it works. why not give it a try?"
```
</markdown>
```
2024-08-31 15:46:23 - Character count: 292
2024-08-31 15:46:23 - Waiting for 10.93 minutes before next check
2024-08-31 15:46:58 - Twitter bot started
2024-08-31 15:47:00 - Tokens used: 1344, Estimated cost: $0.040320
2024-08-31 15:47:00 - Generated tweet:
```markdown
```markdown
"reading the latest in federated learning - found it intriguing that we're essentially turning every device into a mini research lab. what if we applied this distributed learning approach to our own personal growth journeys?"
```
</markdown>
```
2024-08-31 15:47:00 - Character count: 269
2024-08-31 15:47:00 - Waiting for 18.23 minutes before next check
2024-08-31 15:50:33 - Twitter bot started
2024-08-31 15:50:38 - Tokens used: 1358, Estimated cost: $0.040740
2024-08-31 15:50:38 - Generated tweet:
```markdown
"just dove into 'attention is all you need' again. realisation: it's not just about nlp. it's a lesson in focusing on what matters when solving problems. reminds me that in ai, and in life, sometimes the best solutions are the simplest."
```
</markdown>
2024-08-31 15:50:38 - Character count: 265
2024-08-31 15:50:38 - Line count: 4
2024-08-31 15:50:38 - Waiting for 13.67 minutes before next check
2024-08-31 15:55:10 - Twitter bot started
2024-08-31 15:55:10 - An error occurred during the tweet generation process
Traceback (most recent call last):
  File "/Users/sanchaythalnerkar/AI Agents/twitteragent/main.py", line 25, in tweet_loop
    tweet_content = generate_tweet_content()
  File "/Users/sanchaythalnerkar/AI Agents/twitteragent/twitter_utils.py", line 330, in generate_tweet_content
    response = openai.ChatCompletion.create(
  File "/Users/sanchaythalnerkar/AI Agents/twitteragent/twitterenv/lib/python3.10/site-packages/openai/lib/_old_api.py", line 39, in __call__
    raise APIRemovedInV1(symbol=self._symbol)
openai.lib._old_api.APIRemovedInV1: 

You tried to access openai.ChatCompletion, but this is no longer supported in openai>=1.0.0 - see the README at https://github.com/openai/openai-python for the API.

You can run `openai migrate` to automatically upgrade your codebase to use the 1.0.0 interface. 

Alternatively, you can pin your installation to the old version, e.g. `pip install openai==0.28`

A detailed migration guide is available here: https://github.com/openai/openai-python/discussions/742

2024-08-31 15:55:10 - Waiting for 17.05 minutes before next check
2024-08-31 15:56:06 - Twitter bot started
2024-08-31 15:56:06 - Skipped tweeting this interval
2024-08-31 15:56:06 - Waiting for 11.72 minutes before next check
2024-08-31 15:56:12 - Twitter bot started
2024-08-31 15:56:13 - Generated tweet:
book_takeaway: failure isn't a setback but a step toward refinement. embrace and iterate.
2024-08-31 15:56:13 - Character count: 89
2024-08-31 15:56:13 - Line count: 1
2024-08-31 15:56:13 - Waiting for 16.82 minutes before next check
2024-08-31 16:00:22 - Twitter bot started
2024-08-31 16:00:23 - Generated tweet:
quantum computing will redefine ML possibilities; exponential speedups in complex problem solving.
2024-08-31 16:00:23 - Character count: 98
2024-08-31 16:00:23 - Line count: 1
2024-08-31 16:00:23 - Waiting for 15.40 minutes before next check
2024-08-31 16:01:12 - Twitter bot started
2024-08-31 16:01:13 - Generated tweet:
define your top 3 tasks daily. clarity drives focus; focus drives productivity.
2024-08-31 16:01:13 - Character count: 79
2024-08-31 16:01:13 - Line count: 1
2024-08-31 16:01:14 - Twitter API response: {
    "data": {
        "edit_history_tweet_ids": [
            "1829829291812548694"
        ],
        "id": "1829829291812548694",
        "text": "define your top 3 tasks daily. clarity drives focus; focus drives productivity."
    }
}
2024-08-31 16:01:14 - Waiting for 12.45 minutes before next check
2024-09-01 09:12:35 - Retrying request to /chat/completions in 0.805598 seconds
2024-09-01 09:12:35 - Retrying request to /chat/completions in 1.886007 seconds
2024-09-01 09:12:37 - An error occurred during the tweet process
Traceback (most recent call last):
  File "/Users/sanchaythalnerkar/AI Agents/twitteragent/twitterenv/lib/python3.10/site-packages/httpcore/_exceptions.py", line 8, in map_exceptions
    yield
  File "/Users/sanchaythalnerkar/AI Agents/twitteragent/twitterenv/lib/python3.10/site-packages/httpcore/backends/sync.py", line 86, in connect_tcp
    sock = socket.create_connection(
  File "/opt/homebrew/Cellar/python@3.10/3.10.14_1/Frameworks/Python.framework/Versions/3.10/lib/python3.10/socket.py", line 824, in create_connection
    for res in getaddrinfo(host, port, 0, SOCK_STREAM):
  File "/opt/homebrew/Cellar/python@3.10/3.10.14_1/Frameworks/Python.framework/Versions/3.10/lib/python3.10/socket.py", line 955, in getaddrinfo
    for res in _socket.getaddrinfo(host, port, family, type, proto, flags):
socket.gaierror: [Errno 8] nodename nor servname provided, or not known

During handling of the above exception, another exception occurred:

Traceback (most recent call last):
  File "/Users/sanchaythalnerkar/AI Agents/twitteragent/twitterenv/lib/python3.10/site-packages/httpx/_transports/default.py", line 60, in map_httpcore_exceptions
    yield
  File "/Users/sanchaythalnerkar/AI Agents/twitteragent/twitterenv/lib/python3.10/site-packages/httpx/_transports/default.py", line 218, in handle_request
    resp = self._pool.handle_request(req)
  File "/Users/sanchaythalnerkar/AI Agents/twitteragent/twitterenv/lib/python3.10/site-packages/httpcore/_sync/connection_pool.py", line 253, in handle_request
    raise exc
  File "/Users/sanchaythalnerkar/AI Agents/twitteragent/twitterenv/lib/python3.10/site-packages/httpcore/_sync/connection_pool.py", line 237, in handle_request
    response = connection.handle_request(request)
  File "/Users/sanchaythalnerkar/AI Agents/twitteragent/twitterenv/lib/python3.10/site-packages/httpcore/_sync/connection.py", line 86, in handle_request
    raise exc
  File "/Users/sanchaythalnerkar/AI Agents/twitteragent/twitterenv/lib/python3.10/site-packages/httpcore/_sync/connection.py", line 63, in handle_request
    stream = self._connect(request)
  File "/Users/sanchaythalnerkar/AI Agents/twitteragent/twitterenv/lib/python3.10/site-packages/httpcore/_sync/connection.py", line 111, in _connect
    stream = self._network_backend.connect_tcp(**kwargs)
  File "/Users/sanchaythalnerkar/AI Agents/twitteragent/twitterenv/lib/python3.10/site-packages/httpcore/backends/sync.py", line 85, in connect_tcp
    with map_exceptions(exc_map):
  File "/opt/homebrew/Cellar/python@3.10/3.10.14_1/Frameworks/Python.framework/Versions/3.10/lib/python3.10/contextlib.py", line 153, in __exit__
    self.gen.throw(typ, value, traceback)
  File "/Users/sanchaythalnerkar/AI Agents/twitteragent/twitterenv/lib/python3.10/site-packages/httpcore/_exceptions.py", line 12, in map_exceptions
    raise to_exc(exc)
httpcore.ConnectError: [Errno 8] nodename nor servname provided, or not known

The above exception was the direct cause of the following exception:

Traceback (most recent call last):
  File "/Users/sanchaythalnerkar/AI Agents/twitteragent/twitterenv/lib/python3.10/site-packages/openai/_base_client.py", line 973, in _request
    response = self._client.send(
  File "/Users/sanchaythalnerkar/AI Agents/twitteragent/twitterenv/lib/python3.10/site-packages/httpx/_client.py", line 902, in send
    response = self._send_handling_auth(
  File "/Users/sanchaythalnerkar/AI Agents/twitteragent/twitterenv/lib/python3.10/site-packages/httpx/_client.py", line 930, in _send_handling_auth
    response = self._send_handling_redirects(
  File "/Users/sanchaythalnerkar/AI Agents/twitteragent/twitterenv/lib/python3.10/site-packages/httpx/_client.py", line 967, in _send_handling_redirects
    response = self._send_single_request(request)
  File "/Users/sanchaythalnerkar/AI Agents/twitteragent/twitterenv/lib/python3.10/site-packages/httpx/_client.py", line 1003, in _send_single_request
    response = transport.handle_request(request)
  File "/Users/sanchaythalnerkar/AI Agents/twitteragent/twitterenv/lib/python3.10/site-packages/httpx/_transports/default.py", line 217, in handle_request
    with map_httpcore_exceptions():
  File "/opt/homebrew/Cellar/python@3.10/3.10.14_1/Frameworks/Python.framework/Versions/3.10/lib/python3.10/contextlib.py", line 153, in __exit__
    self.gen.throw(typ, value, traceback)
  File "/Users/sanchaythalnerkar/AI Agents/twitteragent/twitterenv/lib/python3.10/site-packages/httpx/_transports/default.py", line 77, in map_httpcore_exceptions
    raise mapped_exc(message) from exc
httpx.ConnectError: [Errno 8] nodename nor servname provided, or not known

During handling of the above exception, another exception occurred:

Traceback (most recent call last):
  File "/Users/sanchaythalnerkar/AI Agents/twitteragent/twitterenv/lib/python3.10/site-packages/httpcore/_exceptions.py", line 8, in map_exceptions
    yield
  File "/Users/sanchaythalnerkar/AI Agents/twitteragent/twitterenv/lib/python3.10/site-packages/httpcore/backends/sync.py", line 86, in connect_tcp
    sock = socket.create_connection(
  File "/opt/homebrew/Cellar/python@3.10/3.10.14_1/Frameworks/Python.framework/Versions/3.10/lib/python3.10/socket.py", line 824, in create_connection
    for res in getaddrinfo(host, port, 0, SOCK_STREAM):
  File "/opt/homebrew/Cellar/python@3.10/3.10.14_1/Frameworks/Python.framework/Versions/3.10/lib/python3.10/socket.py", line 955, in getaddrinfo
    for res in _socket.getaddrinfo(host, port, family, type, proto, flags):
socket.gaierror: [Errno 8] nodename nor servname provided, or not known

During handling of the above exception, another exception occurred:

Traceback (most recent call last):
  File "/Users/sanchaythalnerkar/AI Agents/twitteragent/twitterenv/lib/python3.10/site-packages/httpx/_transports/default.py", line 60, in map_httpcore_exceptions
    yield
  File "/Users/sanchaythalnerkar/AI Agents/twitteragent/twitterenv/lib/python3.10/site-packages/httpx/_transports/default.py", line 218, in handle_request
    resp = self._pool.handle_request(req)
  File "/Users/sanchaythalnerkar/AI Agents/twitteragent/twitterenv/lib/python3.10/site-packages/httpcore/_sync/connection_pool.py", line 253, in handle_request
    raise exc
  File "/Users/sanchaythalnerkar/AI Agents/twitteragent/twitterenv/lib/python3.10/site-packages/httpcore/_sync/connection_pool.py", line 237, in handle_request
    response = connection.handle_request(request)
  File "/Users/sanchaythalnerkar/AI Agents/twitteragent/twitterenv/lib/python3.10/site-packages/httpcore/_sync/connection.py", line 86, in handle_request
    raise exc
  File "/Users/sanchaythalnerkar/AI Agents/twitteragent/twitterenv/lib/python3.10/site-packages/httpcore/_sync/connection.py", line 63, in handle_request
    stream = self._connect(request)
  File "/Users/sanchaythalnerkar/AI Agents/twitteragent/twitterenv/lib/python3.10/site-packages/httpcore/_sync/connection.py", line 111, in _connect
    stream = self._network_backend.connect_tcp(**kwargs)
  File "/Users/sanchaythalnerkar/AI Agents/twitteragent/twitterenv/lib/python3.10/site-packages/httpcore/backends/sync.py", line 85, in connect_tcp
    with map_exceptions(exc_map):
  File "/opt/homebrew/Cellar/python@3.10/3.10.14_1/Frameworks/Python.framework/Versions/3.10/lib/python3.10/contextlib.py", line 153, in __exit__
    self.gen.throw(typ, value, traceback)
  File "/Users/sanchaythalnerkar/AI Agents/twitteragent/twitterenv/lib/python3.10/site-packages/httpcore/_exceptions.py", line 12, in map_exceptions
    raise to_exc(exc)
httpcore.ConnectError: [Errno 8] nodename nor servname provided, or not known

The above exception was the direct cause of the following exception:

Traceback (most recent call last):
  File "/Users/sanchaythalnerkar/AI Agents/twitteragent/twitterenv/lib/python3.10/site-packages/openai/_base_client.py", line 973, in _request
    response = self._client.send(
  File "/Users/sanchaythalnerkar/AI Agents/twitteragent/twitterenv/lib/python3.10/site-packages/httpx/_client.py", line 902, in send
    response = self._send_handling_auth(
  File "/Users/sanchaythalnerkar/AI Agents/twitteragent/twitterenv/lib/python3.10/site-packages/httpx/_client.py", line 930, in _send_handling_auth
    response = self._send_handling_redirects(
  File "/Users/sanchaythalnerkar/AI Agents/twitteragent/twitterenv/lib/python3.10/site-packages/httpx/_client.py", line 967, in _send_handling_redirects
    response = self._send_single_request(request)
  File "/Users/sanchaythalnerkar/AI Agents/twitteragent/twitterenv/lib/python3.10/site-packages/httpx/_client.py", line 1003, in _send_single_request
    response = transport.handle_request(request)
  File "/Users/sanchaythalnerkar/AI Agents/twitteragent/twitterenv/lib/python3.10/site-packages/httpx/_transports/default.py", line 217, in handle_request
    with map_httpcore_exceptions():
  File "/opt/homebrew/Cellar/python@3.10/3.10.14_1/Frameworks/Python.framework/Versions/3.10/lib/python3.10/contextlib.py", line 153, in __exit__
    self.gen.throw(typ, value, traceback)
  File "/Users/sanchaythalnerkar/AI Agents/twitteragent/twitterenv/lib/python3.10/site-packages/httpx/_transports/default.py", line 77, in map_httpcore_exceptions
    raise mapped_exc(message) from exc
httpx.ConnectError: [Errno 8] nodename nor servname provided, or not known

During handling of the above exception, another exception occurred:

Traceback (most recent call last):
  File "/Users/sanchaythalnerkar/AI Agents/twitteragent/twitterenv/lib/python3.10/site-packages/httpcore/_exceptions.py", line 8, in map_exceptions
    yield
  File "/Users/sanchaythalnerkar/AI Agents/twitteragent/twitterenv/lib/python3.10/site-packages/httpcore/backends/sync.py", line 86, in connect_tcp
    sock = socket.create_connection(
  File "/opt/homebrew/Cellar/python@3.10/3.10.14_1/Frameworks/Python.framework/Versions/3.10/lib/python3.10/socket.py", line 824, in create_connection
    for res in getaddrinfo(host, port, 0, SOCK_STREAM):
  File "/opt/homebrew/Cellar/python@3.10/3.10.14_1/Frameworks/Python.framework/Versions/3.10/lib/python3.10/socket.py", line 955, in getaddrinfo
    for res in _socket.getaddrinfo(host, port, family, type, proto, flags):
socket.gaierror: [Errno 8] nodename nor servname provided, or not known

During handling of the above exception, another exception occurred:

Traceback (most recent call last):
  File "/Users/sanchaythalnerkar/AI Agents/twitteragent/twitterenv/lib/python3.10/site-packages/httpx/_transports/default.py", line 60, in map_httpcore_exceptions
    yield
  File "/Users/sanchaythalnerkar/AI Agents/twitteragent/twitterenv/lib/python3.10/site-packages/httpx/_transports/default.py", line 218, in handle_request
    resp = self._pool.handle_request(req)
  File "/Users/sanchaythalnerkar/AI Agents/twitteragent/twitterenv/lib/python3.10/site-packages/httpcore/_sync/connection_pool.py", line 253, in handle_request
    raise exc
  File "/Users/sanchaythalnerkar/AI Agents/twitteragent/twitterenv/lib/python3.10/site-packages/httpcore/_sync/connection_pool.py", line 237, in handle_request
    response = connection.handle_request(request)
  File "/Users/sanchaythalnerkar/AI Agents/twitteragent/twitterenv/lib/python3.10/site-packages/httpcore/_sync/connection.py", line 86, in handle_request
    raise exc
  File "/Users/sanchaythalnerkar/AI Agents/twitteragent/twitterenv/lib/python3.10/site-packages/httpcore/_sync/connection.py", line 63, in handle_request
    stream = self._connect(request)
  File "/Users/sanchaythalnerkar/AI Agents/twitteragent/twitterenv/lib/python3.10/site-packages/httpcore/_sync/connection.py", line 111, in _connect
    stream = self._network_backend.connect_tcp(**kwargs)
  File "/Users/sanchaythalnerkar/AI Agents/twitteragent/twitterenv/lib/python3.10/site-packages/httpcore/backends/sync.py", line 85, in connect_tcp
    with map_exceptions(exc_map):
  File "/opt/homebrew/Cellar/python@3.10/3.10.14_1/Frameworks/Python.framework/Versions/3.10/lib/python3.10/contextlib.py", line 153, in __exit__
    self.gen.throw(typ, value, traceback)
  File "/Users/sanchaythalnerkar/AI Agents/twitteragent/twitterenv/lib/python3.10/site-packages/httpcore/_exceptions.py", line 12, in map_exceptions
    raise to_exc(exc)
httpcore.ConnectError: [Errno 8] nodename nor servname provided, or not known

The above exception was the direct cause of the following exception:

Traceback (most recent call last):
  File "/Users/sanchaythalnerkar/AI Agents/twitteragent/twitterenv/lib/python3.10/site-packages/openai/_base_client.py", line 973, in _request
    response = self._client.send(
  File "/Users/sanchaythalnerkar/AI Agents/twitteragent/twitterenv/lib/python3.10/site-packages/httpx/_client.py", line 902, in send
    response = self._send_handling_auth(
  File "/Users/sanchaythalnerkar/AI Agents/twitteragent/twitterenv/lib/python3.10/site-packages/httpx/_client.py", line 930, in _send_handling_auth
    response = self._send_handling_redirects(
  File "/Users/sanchaythalnerkar/AI Agents/twitteragent/twitterenv/lib/python3.10/site-packages/httpx/_client.py", line 967, in _send_handling_redirects
    response = self._send_single_request(request)
  File "/Users/sanchaythalnerkar/AI Agents/twitteragent/twitterenv/lib/python3.10/site-packages/httpx/_client.py", line 1003, in _send_single_request
    response = transport.handle_request(request)
  File "/Users/sanchaythalnerkar/AI Agents/twitteragent/twitterenv/lib/python3.10/site-packages/httpx/_transports/default.py", line 217, in handle_request
    with map_httpcore_exceptions():
  File "/opt/homebrew/Cellar/python@3.10/3.10.14_1/Frameworks/Python.framework/Versions/3.10/lib/python3.10/contextlib.py", line 153, in __exit__
    self.gen.throw(typ, value, traceback)
  File "/Users/sanchaythalnerkar/AI Agents/twitteragent/twitterenv/lib/python3.10/site-packages/httpx/_transports/default.py", line 77, in map_httpcore_exceptions
    raise mapped_exc(message) from exc
httpx.ConnectError: [Errno 8] nodename nor servname provided, or not known

The above exception was the direct cause of the following exception:

Traceback (most recent call last):
  File "/Users/sanchaythalnerkar/AI Agents/twitteragent/main.py", line 25, in tweet_loop
    tweet_content = generate_tweet_content()
  File "/Users/sanchaythalnerkar/AI Agents/twitteragent/twitter_utils.py", line 326, in generate_tweet_content
    response = client.chat.completions.create(
  File "/Users/sanchaythalnerkar/AI Agents/twitteragent/twitterenv/lib/python3.10/site-packages/openai/_utils/_utils.py", line 274, in wrapper
    return func(*args, **kwargs)
  File "/Users/sanchaythalnerkar/AI Agents/twitteragent/twitterenv/lib/python3.10/site-packages/openai/resources/chat/completions.py", line 668, in create
    return self._post(
  File "/Users/sanchaythalnerkar/AI Agents/twitteragent/twitterenv/lib/python3.10/site-packages/openai/_base_client.py", line 1260, in post
    return cast(ResponseT, self.request(cast_to, opts, stream=stream, stream_cls=stream_cls))
  File "/Users/sanchaythalnerkar/AI Agents/twitteragent/twitterenv/lib/python3.10/site-packages/openai/_base_client.py", line 937, in request
    return self._request(
  File "/Users/sanchaythalnerkar/AI Agents/twitteragent/twitterenv/lib/python3.10/site-packages/openai/_base_client.py", line 997, in _request
    return self._retry_request(
  File "/Users/sanchaythalnerkar/AI Agents/twitteragent/twitterenv/lib/python3.10/site-packages/openai/_base_client.py", line 1075, in _retry_request
    return self._request(
  File "/Users/sanchaythalnerkar/AI Agents/twitteragent/twitterenv/lib/python3.10/site-packages/openai/_base_client.py", line 997, in _request
    return self._retry_request(
  File "/Users/sanchaythalnerkar/AI Agents/twitteragent/twitterenv/lib/python3.10/site-packages/openai/_base_client.py", line 1075, in _retry_request
    return self._request(
  File "/Users/sanchaythalnerkar/AI Agents/twitteragent/twitterenv/lib/python3.10/site-packages/openai/_base_client.py", line 1007, in _request
    raise APIConnectionError(request=request) from err
openai.APIConnectionError: Connection error.
2024-09-01 09:12:37 - Waiting for 12.08 minutes before next check
2024-09-01 11:50:49 - Retrying request to /chat/completions in 0.780013 seconds
2024-09-01 11:50:50 - Retrying request to /chat/completions in 1.996997 seconds
2024-09-01 11:50:52 - An error occurred during the tweet process
Traceback (most recent call last):
  File "/Users/sanchaythalnerkar/AI Agents/twitteragent/twitterenv/lib/python3.10/site-packages/httpcore/_exceptions.py", line 8, in map_exceptions
    yield
  File "/Users/sanchaythalnerkar/AI Agents/twitteragent/twitterenv/lib/python3.10/site-packages/httpcore/backends/sync.py", line 86, in connect_tcp
    sock = socket.create_connection(
  File "/opt/homebrew/Cellar/python@3.10/3.10.14_1/Frameworks/Python.framework/Versions/3.10/lib/python3.10/socket.py", line 824, in create_connection
    for res in getaddrinfo(host, port, 0, SOCK_STREAM):
  File "/opt/homebrew/Cellar/python@3.10/3.10.14_1/Frameworks/Python.framework/Versions/3.10/lib/python3.10/socket.py", line 955, in getaddrinfo
    for res in _socket.getaddrinfo(host, port, family, type, proto, flags):
socket.gaierror: [Errno 8] nodename nor servname provided, or not known

During handling of the above exception, another exception occurred:

Traceback (most recent call last):
  File "/Users/sanchaythalnerkar/AI Agents/twitteragent/twitterenv/lib/python3.10/site-packages/httpx/_transports/default.py", line 60, in map_httpcore_exceptions
    yield
  File "/Users/sanchaythalnerkar/AI Agents/twitteragent/twitterenv/lib/python3.10/site-packages/httpx/_transports/default.py", line 218, in handle_request
    resp = self._pool.handle_request(req)
  File "/Users/sanchaythalnerkar/AI Agents/twitteragent/twitterenv/lib/python3.10/site-packages/httpcore/_sync/connection_pool.py", line 253, in handle_request
    raise exc
  File "/Users/sanchaythalnerkar/AI Agents/twitteragent/twitterenv/lib/python3.10/site-packages/httpcore/_sync/connection_pool.py", line 237, in handle_request
    response = connection.handle_request(request)
  File "/Users/sanchaythalnerkar/AI Agents/twitteragent/twitterenv/lib/python3.10/site-packages/httpcore/_sync/connection.py", line 86, in handle_request
    raise exc
  File "/Users/sanchaythalnerkar/AI Agents/twitteragent/twitterenv/lib/python3.10/site-packages/httpcore/_sync/connection.py", line 63, in handle_request
    stream = self._connect(request)
  File "/Users/sanchaythalnerkar/AI Agents/twitteragent/twitterenv/lib/python3.10/site-packages/httpcore/_sync/connection.py", line 111, in _connect
    stream = self._network_backend.connect_tcp(**kwargs)
  File "/Users/sanchaythalnerkar/AI Agents/twitteragent/twitterenv/lib/python3.10/site-packages/httpcore/backends/sync.py", line 85, in connect_tcp
    with map_exceptions(exc_map):
  File "/opt/homebrew/Cellar/python@3.10/3.10.14_1/Frameworks/Python.framework/Versions/3.10/lib/python3.10/contextlib.py", line 153, in __exit__
    self.gen.throw(typ, value, traceback)
  File "/Users/sanchaythalnerkar/AI Agents/twitteragent/twitterenv/lib/python3.10/site-packages/httpcore/_exceptions.py", line 12, in map_exceptions
    raise to_exc(exc)
httpcore.ConnectError: [Errno 8] nodename nor servname provided, or not known

The above exception was the direct cause of the following exception:

Traceback (most recent call last):
  File "/Users/sanchaythalnerkar/AI Agents/twitteragent/twitterenv/lib/python3.10/site-packages/openai/_base_client.py", line 973, in _request
    response = self._client.send(
  File "/Users/sanchaythalnerkar/AI Agents/twitteragent/twitterenv/lib/python3.10/site-packages/httpx/_client.py", line 902, in send
    response = self._send_handling_auth(
  File "/Users/sanchaythalnerkar/AI Agents/twitteragent/twitterenv/lib/python3.10/site-packages/httpx/_client.py", line 930, in _send_handling_auth
    response = self._send_handling_redirects(
  File "/Users/sanchaythalnerkar/AI Agents/twitteragent/twitterenv/lib/python3.10/site-packages/httpx/_client.py", line 967, in _send_handling_redirects
    response = self._send_single_request(request)
  File "/Users/sanchaythalnerkar/AI Agents/twitteragent/twitterenv/lib/python3.10/site-packages/httpx/_client.py", line 1003, in _send_single_request
    response = transport.handle_request(request)
  File "/Users/sanchaythalnerkar/AI Agents/twitteragent/twitterenv/lib/python3.10/site-packages/httpx/_transports/default.py", line 217, in handle_request
    with map_httpcore_exceptions():
  File "/opt/homebrew/Cellar/python@3.10/3.10.14_1/Frameworks/Python.framework/Versions/3.10/lib/python3.10/contextlib.py", line 153, in __exit__
    self.gen.throw(typ, value, traceback)
  File "/Users/sanchaythalnerkar/AI Agents/twitteragent/twitterenv/lib/python3.10/site-packages/httpx/_transports/default.py", line 77, in map_httpcore_exceptions
    raise mapped_exc(message) from exc
httpx.ConnectError: [Errno 8] nodename nor servname provided, or not known

During handling of the above exception, another exception occurred:

Traceback (most recent call last):
  File "/Users/sanchaythalnerkar/AI Agents/twitteragent/twitterenv/lib/python3.10/site-packages/httpcore/_exceptions.py", line 8, in map_exceptions
    yield
  File "/Users/sanchaythalnerkar/AI Agents/twitteragent/twitterenv/lib/python3.10/site-packages/httpcore/backends/sync.py", line 86, in connect_tcp
    sock = socket.create_connection(
  File "/opt/homebrew/Cellar/python@3.10/3.10.14_1/Frameworks/Python.framework/Versions/3.10/lib/python3.10/socket.py", line 824, in create_connection
    for res in getaddrinfo(host, port, 0, SOCK_STREAM):
  File "/opt/homebrew/Cellar/python@3.10/3.10.14_1/Frameworks/Python.framework/Versions/3.10/lib/python3.10/socket.py", line 955, in getaddrinfo
    for res in _socket.getaddrinfo(host, port, family, type, proto, flags):
socket.gaierror: [Errno 8] nodename nor servname provided, or not known

During handling of the above exception, another exception occurred:

Traceback (most recent call last):
  File "/Users/sanchaythalnerkar/AI Agents/twitteragent/twitterenv/lib/python3.10/site-packages/httpx/_transports/default.py", line 60, in map_httpcore_exceptions
    yield
  File "/Users/sanchaythalnerkar/AI Agents/twitteragent/twitterenv/lib/python3.10/site-packages/httpx/_transports/default.py", line 218, in handle_request
    resp = self._pool.handle_request(req)
  File "/Users/sanchaythalnerkar/AI Agents/twitteragent/twitterenv/lib/python3.10/site-packages/httpcore/_sync/connection_pool.py", line 253, in handle_request
    raise exc
  File "/Users/sanchaythalnerkar/AI Agents/twitteragent/twitterenv/lib/python3.10/site-packages/httpcore/_sync/connection_pool.py", line 237, in handle_request
    response = connection.handle_request(request)
  File "/Users/sanchaythalnerkar/AI Agents/twitteragent/twitterenv/lib/python3.10/site-packages/httpcore/_sync/connection.py", line 86, in handle_request
    raise exc
  File "/Users/sanchaythalnerkar/AI Agents/twitteragent/twitterenv/lib/python3.10/site-packages/httpcore/_sync/connection.py", line 63, in handle_request
    stream = self._connect(request)
  File "/Users/sanchaythalnerkar/AI Agents/twitteragent/twitterenv/lib/python3.10/site-packages/httpcore/_sync/connection.py", line 111, in _connect
    stream = self._network_backend.connect_tcp(**kwargs)
  File "/Users/sanchaythalnerkar/AI Agents/twitteragent/twitterenv/lib/python3.10/site-packages/httpcore/backends/sync.py", line 85, in connect_tcp
    with map_exceptions(exc_map):
  File "/opt/homebrew/Cellar/python@3.10/3.10.14_1/Frameworks/Python.framework/Versions/3.10/lib/python3.10/contextlib.py", line 153, in __exit__
    self.gen.throw(typ, value, traceback)
  File "/Users/sanchaythalnerkar/AI Agents/twitteragent/twitterenv/lib/python3.10/site-packages/httpcore/_exceptions.py", line 12, in map_exceptions
    raise to_exc(exc)
httpcore.ConnectError: [Errno 8] nodename nor servname provided, or not known

The above exception was the direct cause of the following exception:

Traceback (most recent call last):
  File "/Users/sanchaythalnerkar/AI Agents/twitteragent/twitterenv/lib/python3.10/site-packages/openai/_base_client.py", line 973, in _request
    response = self._client.send(
  File "/Users/sanchaythalnerkar/AI Agents/twitteragent/twitterenv/lib/python3.10/site-packages/httpx/_client.py", line 902, in send
    response = self._send_handling_auth(
  File "/Users/sanchaythalnerkar/AI Agents/twitteragent/twitterenv/lib/python3.10/site-packages/httpx/_client.py", line 930, in _send_handling_auth
    response = self._send_handling_redirects(
  File "/Users/sanchaythalnerkar/AI Agents/twitteragent/twitterenv/lib/python3.10/site-packages/httpx/_client.py", line 967, in _send_handling_redirects
    response = self._send_single_request(request)
  File "/Users/sanchaythalnerkar/AI Agents/twitteragent/twitterenv/lib/python3.10/site-packages/httpx/_client.py", line 1003, in _send_single_request
    response = transport.handle_request(request)
  File "/Users/sanchaythalnerkar/AI Agents/twitteragent/twitterenv/lib/python3.10/site-packages/httpx/_transports/default.py", line 217, in handle_request
    with map_httpcore_exceptions():
  File "/opt/homebrew/Cellar/python@3.10/3.10.14_1/Frameworks/Python.framework/Versions/3.10/lib/python3.10/contextlib.py", line 153, in __exit__
    self.gen.throw(typ, value, traceback)
  File "/Users/sanchaythalnerkar/AI Agents/twitteragent/twitterenv/lib/python3.10/site-packages/httpx/_transports/default.py", line 77, in map_httpcore_exceptions
    raise mapped_exc(message) from exc
httpx.ConnectError: [Errno 8] nodename nor servname provided, or not known

During handling of the above exception, another exception occurred:

Traceback (most recent call last):
  File "/Users/sanchaythalnerkar/AI Agents/twitteragent/twitterenv/lib/python3.10/site-packages/httpcore/_exceptions.py", line 8, in map_exceptions
    yield
  File "/Users/sanchaythalnerkar/AI Agents/twitteragent/twitterenv/lib/python3.10/site-packages/httpcore/backends/sync.py", line 86, in connect_tcp
    sock = socket.create_connection(
  File "/opt/homebrew/Cellar/python@3.10/3.10.14_1/Frameworks/Python.framework/Versions/3.10/lib/python3.10/socket.py", line 824, in create_connection
    for res in getaddrinfo(host, port, 0, SOCK_STREAM):
  File "/opt/homebrew/Cellar/python@3.10/3.10.14_1/Frameworks/Python.framework/Versions/3.10/lib/python3.10/socket.py", line 955, in getaddrinfo
    for res in _socket.getaddrinfo(host, port, family, type, proto, flags):
socket.gaierror: [Errno 8] nodename nor servname provided, or not known

During handling of the above exception, another exception occurred:

Traceback (most recent call last):
  File "/Users/sanchaythalnerkar/AI Agents/twitteragent/twitterenv/lib/python3.10/site-packages/httpx/_transports/default.py", line 60, in map_httpcore_exceptions
    yield
  File "/Users/sanchaythalnerkar/AI Agents/twitteragent/twitterenv/lib/python3.10/site-packages/httpx/_transports/default.py", line 218, in handle_request
    resp = self._pool.handle_request(req)
  File "/Users/sanchaythalnerkar/AI Agents/twitteragent/twitterenv/lib/python3.10/site-packages/httpcore/_sync/connection_pool.py", line 253, in handle_request
    raise exc
  File "/Users/sanchaythalnerkar/AI Agents/twitteragent/twitterenv/lib/python3.10/site-packages/httpcore/_sync/connection_pool.py", line 237, in handle_request
    response = connection.handle_request(request)
  File "/Users/sanchaythalnerkar/AI Agents/twitteragent/twitterenv/lib/python3.10/site-packages/httpcore/_sync/connection.py", line 86, in handle_request
    raise exc
  File "/Users/sanchaythalnerkar/AI Agents/twitteragent/twitterenv/lib/python3.10/site-packages/httpcore/_sync/connection.py", line 63, in handle_request
    stream = self._connect(request)
  File "/Users/sanchaythalnerkar/AI Agents/twitteragent/twitterenv/lib/python3.10/site-packages/httpcore/_sync/connection.py", line 111, in _connect
    stream = self._network_backend.connect_tcp(**kwargs)
  File "/Users/sanchaythalnerkar/AI Agents/twitteragent/twitterenv/lib/python3.10/site-packages/httpcore/backends/sync.py", line 85, in connect_tcp
    with map_exceptions(exc_map):
  File "/opt/homebrew/Cellar/python@3.10/3.10.14_1/Frameworks/Python.framework/Versions/3.10/lib/python3.10/contextlib.py", line 153, in __exit__
    self.gen.throw(typ, value, traceback)
  File "/Users/sanchaythalnerkar/AI Agents/twitteragent/twitterenv/lib/python3.10/site-packages/httpcore/_exceptions.py", line 12, in map_exceptions
    raise to_exc(exc)
httpcore.ConnectError: [Errno 8] nodename nor servname provided, or not known

The above exception was the direct cause of the following exception:

Traceback (most recent call last):
  File "/Users/sanchaythalnerkar/AI Agents/twitteragent/twitterenv/lib/python3.10/site-packages/openai/_base_client.py", line 973, in _request
    response = self._client.send(
  File "/Users/sanchaythalnerkar/AI Agents/twitteragent/twitterenv/lib/python3.10/site-packages/httpx/_client.py", line 902, in send
    response = self._send_handling_auth(
  File "/Users/sanchaythalnerkar/AI Agents/twitteragent/twitterenv/lib/python3.10/site-packages/httpx/_client.py", line 930, in _send_handling_auth
    response = self._send_handling_redirects(
  File "/Users/sanchaythalnerkar/AI Agents/twitteragent/twitterenv/lib/python3.10/site-packages/httpx/_client.py", line 967, in _send_handling_redirects
    response = self._send_single_request(request)
  File "/Users/sanchaythalnerkar/AI Agents/twitteragent/twitterenv/lib/python3.10/site-packages/httpx/_client.py", line 1003, in _send_single_request
    response = transport.handle_request(request)
  File "/Users/sanchaythalnerkar/AI Agents/twitteragent/twitterenv/lib/python3.10/site-packages/httpx/_transports/default.py", line 217, in handle_request
    with map_httpcore_exceptions():
  File "/opt/homebrew/Cellar/python@3.10/3.10.14_1/Frameworks/Python.framework/Versions/3.10/lib/python3.10/contextlib.py", line 153, in __exit__
    self.gen.throw(typ, value, traceback)
  File "/Users/sanchaythalnerkar/AI Agents/twitteragent/twitterenv/lib/python3.10/site-packages/httpx/_transports/default.py", line 77, in map_httpcore_exceptions
    raise mapped_exc(message) from exc
httpx.ConnectError: [Errno 8] nodename nor servname provided, or not known

The above exception was the direct cause of the following exception:

Traceback (most recent call last):
  File "/Users/sanchaythalnerkar/AI Agents/twitteragent/main.py", line 25, in tweet_loop
    tweet_content = generate_tweet_content()
  File "/Users/sanchaythalnerkar/AI Agents/twitteragent/twitter_utils.py", line 326, in generate_tweet_content
    response = client.chat.completions.create(
  File "/Users/sanchaythalnerkar/AI Agents/twitteragent/twitterenv/lib/python3.10/site-packages/openai/_utils/_utils.py", line 274, in wrapper
    return func(*args, **kwargs)
  File "/Users/sanchaythalnerkar/AI Agents/twitteragent/twitterenv/lib/python3.10/site-packages/openai/resources/chat/completions.py", line 668, in create
    return self._post(
  File "/Users/sanchaythalnerkar/AI Agents/twitteragent/twitterenv/lib/python3.10/site-packages/openai/_base_client.py", line 1260, in post
    return cast(ResponseT, self.request(cast_to, opts, stream=stream, stream_cls=stream_cls))
  File "/Users/sanchaythalnerkar/AI Agents/twitteragent/twitterenv/lib/python3.10/site-packages/openai/_base_client.py", line 937, in request
    return self._request(
  File "/Users/sanchaythalnerkar/AI Agents/twitteragent/twitterenv/lib/python3.10/site-packages/openai/_base_client.py", line 997, in _request
    return self._retry_request(
  File "/Users/sanchaythalnerkar/AI Agents/twitteragent/twitterenv/lib/python3.10/site-packages/openai/_base_client.py", line 1075, in _retry_request
    return self._request(
  File "/Users/sanchaythalnerkar/AI Agents/twitteragent/twitterenv/lib/python3.10/site-packages/openai/_base_client.py", line 997, in _request
    return self._retry_request(
  File "/Users/sanchaythalnerkar/AI Agents/twitteragent/twitterenv/lib/python3.10/site-packages/openai/_base_client.py", line 1075, in _retry_request
    return self._request(
  File "/Users/sanchaythalnerkar/AI Agents/twitteragent/twitterenv/lib/python3.10/site-packages/openai/_base_client.py", line 1007, in _request
    raise APIConnectionError(request=request) from err
openai.APIConnectionError: Connection error.
2024-09-01 11:50:52 - Waiting for 19.67 minutes before next check
2024-09-01 12:02:11 - Twitter bot stopped
2024-09-01 12:02:14 - Twitter bot started
2024-09-01 12:02:14 - Retrying request to /chat/completions in 0.943188 seconds
2024-09-01 12:02:15 - Retrying request to /chat/completions in 1.960240 seconds
2024-09-01 12:02:17 - An error occurred during the tweet process
Traceback (most recent call last):
  File "/Users/sanchaythalnerkar/AI Agents/twitteragent/twitterenv/lib/python3.10/site-packages/httpcore/_exceptions.py", line 8, in map_exceptions
    yield
  File "/Users/sanchaythalnerkar/AI Agents/twitteragent/twitterenv/lib/python3.10/site-packages/httpcore/backends/sync.py", line 86, in connect_tcp
    sock = socket.create_connection(
  File "/opt/homebrew/Cellar/python@3.10/3.10.14_1/Frameworks/Python.framework/Versions/3.10/lib/python3.10/socket.py", line 824, in create_connection
    for res in getaddrinfo(host, port, 0, SOCK_STREAM):
  File "/opt/homebrew/Cellar/python@3.10/3.10.14_1/Frameworks/Python.framework/Versions/3.10/lib/python3.10/socket.py", line 955, in getaddrinfo
    for res in _socket.getaddrinfo(host, port, family, type, proto, flags):
socket.gaierror: [Errno 8] nodename nor servname provided, or not known

During handling of the above exception, another exception occurred:

Traceback (most recent call last):
  File "/Users/sanchaythalnerkar/AI Agents/twitteragent/twitterenv/lib/python3.10/site-packages/httpx/_transports/default.py", line 60, in map_httpcore_exceptions
    yield
  File "/Users/sanchaythalnerkar/AI Agents/twitteragent/twitterenv/lib/python3.10/site-packages/httpx/_transports/default.py", line 218, in handle_request
    resp = self._pool.handle_request(req)
  File "/Users/sanchaythalnerkar/AI Agents/twitteragent/twitterenv/lib/python3.10/site-packages/httpcore/_sync/connection_pool.py", line 253, in handle_request
    raise exc
  File "/Users/sanchaythalnerkar/AI Agents/twitteragent/twitterenv/lib/python3.10/site-packages/httpcore/_sync/connection_pool.py", line 237, in handle_request
    response = connection.handle_request(request)
  File "/Users/sanchaythalnerkar/AI Agents/twitteragent/twitterenv/lib/python3.10/site-packages/httpcore/_sync/connection.py", line 86, in handle_request
    raise exc
  File "/Users/sanchaythalnerkar/AI Agents/twitteragent/twitterenv/lib/python3.10/site-packages/httpcore/_sync/connection.py", line 63, in handle_request
    stream = self._connect(request)
  File "/Users/sanchaythalnerkar/AI Agents/twitteragent/twitterenv/lib/python3.10/site-packages/httpcore/_sync/connection.py", line 111, in _connect
    stream = self._network_backend.connect_tcp(**kwargs)
  File "/Users/sanchaythalnerkar/AI Agents/twitteragent/twitterenv/lib/python3.10/site-packages/httpcore/backends/sync.py", line 85, in connect_tcp
    with map_exceptions(exc_map):
  File "/opt/homebrew/Cellar/python@3.10/3.10.14_1/Frameworks/Python.framework/Versions/3.10/lib/python3.10/contextlib.py", line 153, in __exit__
    self.gen.throw(typ, value, traceback)
  File "/Users/sanchaythalnerkar/AI Agents/twitteragent/twitterenv/lib/python3.10/site-packages/httpcore/_exceptions.py", line 12, in map_exceptions
    raise to_exc(exc)
httpcore.ConnectError: [Errno 8] nodename nor servname provided, or not known

The above exception was the direct cause of the following exception:

Traceback (most recent call last):
  File "/Users/sanchaythalnerkar/AI Agents/twitteragent/twitterenv/lib/python3.10/site-packages/openai/_base_client.py", line 973, in _request
    response = self._client.send(
  File "/Users/sanchaythalnerkar/AI Agents/twitteragent/twitterenv/lib/python3.10/site-packages/httpx/_client.py", line 902, in send
    response = self._send_handling_auth(
  File "/Users/sanchaythalnerkar/AI Agents/twitteragent/twitterenv/lib/python3.10/site-packages/httpx/_client.py", line 930, in _send_handling_auth
    response = self._send_handling_redirects(
  File "/Users/sanchaythalnerkar/AI Agents/twitteragent/twitterenv/lib/python3.10/site-packages/httpx/_client.py", line 967, in _send_handling_redirects
    response = self._send_single_request(request)
  File "/Users/sanchaythalnerkar/AI Agents/twitteragent/twitterenv/lib/python3.10/site-packages/httpx/_client.py", line 1003, in _send_single_request
    response = transport.handle_request(request)
  File "/Users/sanchaythalnerkar/AI Agents/twitteragent/twitterenv/lib/python3.10/site-packages/httpx/_transports/default.py", line 217, in handle_request
    with map_httpcore_exceptions():
  File "/opt/homebrew/Cellar/python@3.10/3.10.14_1/Frameworks/Python.framework/Versions/3.10/lib/python3.10/contextlib.py", line 153, in __exit__
    self.gen.throw(typ, value, traceback)
  File "/Users/sanchaythalnerkar/AI Agents/twitteragent/twitterenv/lib/python3.10/site-packages/httpx/_transports/default.py", line 77, in map_httpcore_exceptions
    raise mapped_exc(message) from exc
httpx.ConnectError: [Errno 8] nodename nor servname provided, or not known

During handling of the above exception, another exception occurred:

Traceback (most recent call last):
  File "/Users/sanchaythalnerkar/AI Agents/twitteragent/twitterenv/lib/python3.10/site-packages/httpcore/_exceptions.py", line 8, in map_exceptions
    yield
  File "/Users/sanchaythalnerkar/AI Agents/twitteragent/twitterenv/lib/python3.10/site-packages/httpcore/backends/sync.py", line 86, in connect_tcp
    sock = socket.create_connection(
  File "/opt/homebrew/Cellar/python@3.10/3.10.14_1/Frameworks/Python.framework/Versions/3.10/lib/python3.10/socket.py", line 824, in create_connection
    for res in getaddrinfo(host, port, 0, SOCK_STREAM):
  File "/opt/homebrew/Cellar/python@3.10/3.10.14_1/Frameworks/Python.framework/Versions/3.10/lib/python3.10/socket.py", line 955, in getaddrinfo
    for res in _socket.getaddrinfo(host, port, family, type, proto, flags):
socket.gaierror: [Errno 8] nodename nor servname provided, or not known

During handling of the above exception, another exception occurred:

Traceback (most recent call last):
  File "/Users/sanchaythalnerkar/AI Agents/twitteragent/twitterenv/lib/python3.10/site-packages/httpx/_transports/default.py", line 60, in map_httpcore_exceptions
    yield
  File "/Users/sanchaythalnerkar/AI Agents/twitteragent/twitterenv/lib/python3.10/site-packages/httpx/_transports/default.py", line 218, in handle_request
    resp = self._pool.handle_request(req)
  File "/Users/sanchaythalnerkar/AI Agents/twitteragent/twitterenv/lib/python3.10/site-packages/httpcore/_sync/connection_pool.py", line 253, in handle_request
    raise exc
  File "/Users/sanchaythalnerkar/AI Agents/twitteragent/twitterenv/lib/python3.10/site-packages/httpcore/_sync/connection_pool.py", line 237, in handle_request
    response = connection.handle_request(request)
  File "/Users/sanchaythalnerkar/AI Agents/twitteragent/twitterenv/lib/python3.10/site-packages/httpcore/_sync/connection.py", line 86, in handle_request
    raise exc
  File "/Users/sanchaythalnerkar/AI Agents/twitteragent/twitterenv/lib/python3.10/site-packages/httpcore/_sync/connection.py", line 63, in handle_request
    stream = self._connect(request)
  File "/Users/sanchaythalnerkar/AI Agents/twitteragent/twitterenv/lib/python3.10/site-packages/httpcore/_sync/connection.py", line 111, in _connect
    stream = self._network_backend.connect_tcp(**kwargs)
  File "/Users/sanchaythalnerkar/AI Agents/twitteragent/twitterenv/lib/python3.10/site-packages/httpcore/backends/sync.py", line 85, in connect_tcp
    with map_exceptions(exc_map):
  File "/opt/homebrew/Cellar/python@3.10/3.10.14_1/Frameworks/Python.framework/Versions/3.10/lib/python3.10/contextlib.py", line 153, in __exit__
    self.gen.throw(typ, value, traceback)
  File "/Users/sanchaythalnerkar/AI Agents/twitteragent/twitterenv/lib/python3.10/site-packages/httpcore/_exceptions.py", line 12, in map_exceptions
    raise to_exc(exc)
httpcore.ConnectError: [Errno 8] nodename nor servname provided, or not known

The above exception was the direct cause of the following exception:

Traceback (most recent call last):
  File "/Users/sanchaythalnerkar/AI Agents/twitteragent/twitterenv/lib/python3.10/site-packages/openai/_base_client.py", line 973, in _request
    response = self._client.send(
  File "/Users/sanchaythalnerkar/AI Agents/twitteragent/twitterenv/lib/python3.10/site-packages/httpx/_client.py", line 902, in send
    response = self._send_handling_auth(
  File "/Users/sanchaythalnerkar/AI Agents/twitteragent/twitterenv/lib/python3.10/site-packages/httpx/_client.py", line 930, in _send_handling_auth
    response = self._send_handling_redirects(
  File "/Users/sanchaythalnerkar/AI Agents/twitteragent/twitterenv/lib/python3.10/site-packages/httpx/_client.py", line 967, in _send_handling_redirects
    response = self._send_single_request(request)
  File "/Users/sanchaythalnerkar/AI Agents/twitteragent/twitterenv/lib/python3.10/site-packages/httpx/_client.py", line 1003, in _send_single_request
    response = transport.handle_request(request)
  File "/Users/sanchaythalnerkar/AI Agents/twitteragent/twitterenv/lib/python3.10/site-packages/httpx/_transports/default.py", line 217, in handle_request
    with map_httpcore_exceptions():
  File "/opt/homebrew/Cellar/python@3.10/3.10.14_1/Frameworks/Python.framework/Versions/3.10/lib/python3.10/contextlib.py", line 153, in __exit__
    self.gen.throw(typ, value, traceback)
  File "/Users/sanchaythalnerkar/AI Agents/twitteragent/twitterenv/lib/python3.10/site-packages/httpx/_transports/default.py", line 77, in map_httpcore_exceptions
    raise mapped_exc(message) from exc
httpx.ConnectError: [Errno 8] nodename nor servname provided, or not known

During handling of the above exception, another exception occurred:

Traceback (most recent call last):
  File "/Users/sanchaythalnerkar/AI Agents/twitteragent/twitterenv/lib/python3.10/site-packages/httpcore/_exceptions.py", line 8, in map_exceptions
    yield
  File "/Users/sanchaythalnerkar/AI Agents/twitteragent/twitterenv/lib/python3.10/site-packages/httpcore/backends/sync.py", line 86, in connect_tcp
    sock = socket.create_connection(
  File "/opt/homebrew/Cellar/python@3.10/3.10.14_1/Frameworks/Python.framework/Versions/3.10/lib/python3.10/socket.py", line 824, in create_connection
    for res in getaddrinfo(host, port, 0, SOCK_STREAM):
  File "/opt/homebrew/Cellar/python@3.10/3.10.14_1/Frameworks/Python.framework/Versions/3.10/lib/python3.10/socket.py", line 955, in getaddrinfo
    for res in _socket.getaddrinfo(host, port, family, type, proto, flags):
socket.gaierror: [Errno 8] nodename nor servname provided, or not known

During handling of the above exception, another exception occurred:

Traceback (most recent call last):
  File "/Users/sanchaythalnerkar/AI Agents/twitteragent/twitterenv/lib/python3.10/site-packages/httpx/_transports/default.py", line 60, in map_httpcore_exceptions
    yield
  File "/Users/sanchaythalnerkar/AI Agents/twitteragent/twitterenv/lib/python3.10/site-packages/httpx/_transports/default.py", line 218, in handle_request
    resp = self._pool.handle_request(req)
  File "/Users/sanchaythalnerkar/AI Agents/twitteragent/twitterenv/lib/python3.10/site-packages/httpcore/_sync/connection_pool.py", line 253, in handle_request
    raise exc
  File "/Users/sanchaythalnerkar/AI Agents/twitteragent/twitterenv/lib/python3.10/site-packages/httpcore/_sync/connection_pool.py", line 237, in handle_request
    response = connection.handle_request(request)
  File "/Users/sanchaythalnerkar/AI Agents/twitteragent/twitterenv/lib/python3.10/site-packages/httpcore/_sync/connection.py", line 86, in handle_request
    raise exc
  File "/Users/sanchaythalnerkar/AI Agents/twitteragent/twitterenv/lib/python3.10/site-packages/httpcore/_sync/connection.py", line 63, in handle_request
    stream = self._connect(request)
  File "/Users/sanchaythalnerkar/AI Agents/twitteragent/twitterenv/lib/python3.10/site-packages/httpcore/_sync/connection.py", line 111, in _connect
    stream = self._network_backend.connect_tcp(**kwargs)
  File "/Users/sanchaythalnerkar/AI Agents/twitteragent/twitterenv/lib/python3.10/site-packages/httpcore/backends/sync.py", line 85, in connect_tcp
    with map_exceptions(exc_map):
  File "/opt/homebrew/Cellar/python@3.10/3.10.14_1/Frameworks/Python.framework/Versions/3.10/lib/python3.10/contextlib.py", line 153, in __exit__
    self.gen.throw(typ, value, traceback)
  File "/Users/sanchaythalnerkar/AI Agents/twitteragent/twitterenv/lib/python3.10/site-packages/httpcore/_exceptions.py", line 12, in map_exceptions
    raise to_exc(exc)
httpcore.ConnectError: [Errno 8] nodename nor servname provided, or not known

The above exception was the direct cause of the following exception:

Traceback (most recent call last):
  File "/Users/sanchaythalnerkar/AI Agents/twitteragent/twitterenv/lib/python3.10/site-packages/openai/_base_client.py", line 973, in _request
    response = self._client.send(
  File "/Users/sanchaythalnerkar/AI Agents/twitteragent/twitterenv/lib/python3.10/site-packages/httpx/_client.py", line 902, in send
    response = self._send_handling_auth(
  File "/Users/sanchaythalnerkar/AI Agents/twitteragent/twitterenv/lib/python3.10/site-packages/httpx/_client.py", line 930, in _send_handling_auth
    response = self._send_handling_redirects(
  File "/Users/sanchaythalnerkar/AI Agents/twitteragent/twitterenv/lib/python3.10/site-packages/httpx/_client.py", line 967, in _send_handling_redirects
    response = self._send_single_request(request)
  File "/Users/sanchaythalnerkar/AI Agents/twitteragent/twitterenv/lib/python3.10/site-packages/httpx/_client.py", line 1003, in _send_single_request
    response = transport.handle_request(request)
  File "/Users/sanchaythalnerkar/AI Agents/twitteragent/twitterenv/lib/python3.10/site-packages/httpx/_transports/default.py", line 217, in handle_request
    with map_httpcore_exceptions():
  File "/opt/homebrew/Cellar/python@3.10/3.10.14_1/Frameworks/Python.framework/Versions/3.10/lib/python3.10/contextlib.py", line 153, in __exit__
    self.gen.throw(typ, value, traceback)
  File "/Users/sanchaythalnerkar/AI Agents/twitteragent/twitterenv/lib/python3.10/site-packages/httpx/_transports/default.py", line 77, in map_httpcore_exceptions
    raise mapped_exc(message) from exc
httpx.ConnectError: [Errno 8] nodename nor servname provided, or not known

The above exception was the direct cause of the following exception:

Traceback (most recent call last):
  File "/Users/sanchaythalnerkar/AI Agents/twitteragent/main.py", line 25, in tweet_loop
    tweet_content = generate_tweet_content()
  File "/Users/sanchaythalnerkar/AI Agents/twitteragent/twitter_utils.py", line 326, in generate_tweet_content
    response = client.chat.completions.create(
  File "/Users/sanchaythalnerkar/AI Agents/twitteragent/twitterenv/lib/python3.10/site-packages/openai/_utils/_utils.py", line 274, in wrapper
    return func(*args, **kwargs)
  File "/Users/sanchaythalnerkar/AI Agents/twitteragent/twitterenv/lib/python3.10/site-packages/openai/resources/chat/completions.py", line 668, in create
    return self._post(
  File "/Users/sanchaythalnerkar/AI Agents/twitteragent/twitterenv/lib/python3.10/site-packages/openai/_base_client.py", line 1260, in post
    return cast(ResponseT, self.request(cast_to, opts, stream=stream, stream_cls=stream_cls))
  File "/Users/sanchaythalnerkar/AI Agents/twitteragent/twitterenv/lib/python3.10/site-packages/openai/_base_client.py", line 937, in request
    return self._request(
  File "/Users/sanchaythalnerkar/AI Agents/twitteragent/twitterenv/lib/python3.10/site-packages/openai/_base_client.py", line 997, in _request
    return self._retry_request(
  File "/Users/sanchaythalnerkar/AI Agents/twitteragent/twitterenv/lib/python3.10/site-packages/openai/_base_client.py", line 1075, in _retry_request
    return self._request(
  File "/Users/sanchaythalnerkar/AI Agents/twitteragent/twitterenv/lib/python3.10/site-packages/openai/_base_client.py", line 997, in _request
    return self._retry_request(
  File "/Users/sanchaythalnerkar/AI Agents/twitteragent/twitterenv/lib/python3.10/site-packages/openai/_base_client.py", line 1075, in _retry_request
    return self._request(
  File "/Users/sanchaythalnerkar/AI Agents/twitteragent/twitterenv/lib/python3.10/site-packages/openai/_base_client.py", line 1007, in _request
    raise APIConnectionError(request=request) from err
openai.APIConnectionError: Connection error.
2024-09-01 12:02:17 - Waiting for 11.78 minutes before next check
2024-09-01 12:02:20 - Twitter bot stopped
2024-09-01 12:03:22 - Twitter bot started
2024-09-01 12:03:25 - Generated tweet:
automl is democratizing ai, making advanced models accessible without deep expertise.
2024-09-01 12:03:25 - Character count: 85
2024-09-01 12:03:25 - Line count: 1
2024-09-01 12:03:26 - Twitter API response: {
    "data": {
        "edit_history_tweet_ids": [
            "1830131833427919341"
        ],
        "id": "1830131833427919341",
        "text": "automl is democratizing ai, making advanced models accessible without deep expertise."
    }
}
2024-09-01 12:03:26 - Waiting for 16.65 minutes before next check
2024-09-01 12:03:57 - Twitter bot stopped
2024-09-01 15:32:05 - Twitter bot started
2024-09-01 15:32:05 - Skipped tweeting this interval
2024-09-01 15:32:05 - Waiting for 13.82 minutes before next check
2024-09-01 15:32:09 - Twitter bot stopped
2024-09-01 15:32:10 - Twitter bot started
2024-09-01 15:32:11 - Generated tweet:
federated learning enhances privacy by training models without sharing raw data.
2024-09-01 15:32:11 - Character count: 80
2024-09-01 15:32:11 - Line count: 1
2024-09-01 15:32:12 - Twitter API response: {
    "data": {
        "edit_history_tweet_ids": [
            "1830184372051591253"
        ],
        "id": "1830184372051591253",
        "text": "federated learning enhances privacy by training models without sharing raw data."
    }
}
2024-09-01 15:32:12 - Waiting for 17.72 minutes before next check
2024-09-01 17:05:17 - Generated tweet:
great books don’t just inform; they transform. choose wisely.
2024-09-01 17:05:17 - Character count: 61
2024-09-01 17:05:17 - Line count: 1
2024-09-01 17:05:17 - Twitter API response: {
    "data": {
        "edit_history_tweet_ids": [
            "1830207799428813129"
        ],
        "id": "1830207799428813129",
        "text": "great books don\u2019t just inform; they transform. choose wisely."
    }
}
2024-09-01 17:05:17 - Waiting for 14.23 minutes before next check
2024-09-01 17:19:31 - Skipped tweeting this interval
2024-09-01 17:19:31 - Waiting for 13.52 minutes before next check
2024-09-01 17:33:03 - Generated tweet:
tech evolves fast; adaptability is now a core skill. embrace change or risk obsolescence.
2024-09-01 17:33:03 - Character count: 89
2024-09-01 17:33:03 - Line count: 1
2024-09-01 17:33:04 - Twitter API response: {
    "data": {
        "edit_history_tweet_ids": [
            "1830214789437796420"
        ],
        "id": "1830214789437796420",
        "text": "tech evolves fast; adaptability is now a core skill. embrace change or risk obsolescence."
    }
}
2024-09-01 17:33:04 - Waiting for 13.47 minutes before next check
2024-09-01 17:46:33 - Generated tweet:
quantum computing could redefine ML by exponentially accelerating data processing capabilities.
2024-09-01 17:46:33 - Character count: 95
2024-09-01 17:46:33 - Line count: 1
2024-09-01 17:46:33 - Twitter API response: {
    "data": {
        "edit_history_tweet_ids": [
            "1830218184978489638"
        ],
        "id": "1830218184978489638",
        "text": "quantum computing could redefine ML by exponentially accelerating data processing capabilities."
    }
}
2024-09-01 17:46:33 - Waiting for 10.53 minutes before next check
2024-09-01 17:57:43 - Skipped tweeting this interval
2024-09-01 17:57:43 - Waiting for 14.77 minutes before next check
2024-09-01 18:12:30 - Generated tweet:
pivot quickly, but with purpose. agility fuels growth in entrepreneurship.
2024-09-01 18:12:30 - Character count: 74
2024-09-01 18:12:30 - Line count: 1
2024-09-01 18:12:30 - Twitter API response: {
    "data": {
        "edit_history_tweet_ids": [
            "1830224715467939908"
        ],
        "id": "1830224715467939908",
        "text": "pivot quickly, but with purpose. agility fuels growth in entrepreneurship."
    }
}
2024-09-01 18:12:30 - Waiting for 12.00 minutes before next check
2024-09-01 18:31:24 - Retrying request to /chat/completions in 0.984995 seconds
2024-09-01 18:31:25 - Retrying request to /chat/completions in 1.809547 seconds
2024-09-01 18:31:26 - An error occurred during the tweet process
Traceback (most recent call last):
  File "/Users/sanchaythalnerkar/AI Agents/twitteragent/twitterenv/lib/python3.10/site-packages/httpcore/_exceptions.py", line 8, in map_exceptions
    yield
  File "/Users/sanchaythalnerkar/AI Agents/twitteragent/twitterenv/lib/python3.10/site-packages/httpcore/backends/sync.py", line 86, in connect_tcp
    sock = socket.create_connection(
  File "/opt/homebrew/Cellar/python@3.10/3.10.14_1/Frameworks/Python.framework/Versions/3.10/lib/python3.10/socket.py", line 824, in create_connection
    for res in getaddrinfo(host, port, 0, SOCK_STREAM):
  File "/opt/homebrew/Cellar/python@3.10/3.10.14_1/Frameworks/Python.framework/Versions/3.10/lib/python3.10/socket.py", line 955, in getaddrinfo
    for res in _socket.getaddrinfo(host, port, family, type, proto, flags):
socket.gaierror: [Errno 8] nodename nor servname provided, or not known

During handling of the above exception, another exception occurred:

Traceback (most recent call last):
  File "/Users/sanchaythalnerkar/AI Agents/twitteragent/twitterenv/lib/python3.10/site-packages/httpx/_transports/default.py", line 60, in map_httpcore_exceptions
    yield
  File "/Users/sanchaythalnerkar/AI Agents/twitteragent/twitterenv/lib/python3.10/site-packages/httpx/_transports/default.py", line 218, in handle_request
    resp = self._pool.handle_request(req)
  File "/Users/sanchaythalnerkar/AI Agents/twitteragent/twitterenv/lib/python3.10/site-packages/httpcore/_sync/connection_pool.py", line 253, in handle_request
    raise exc
  File "/Users/sanchaythalnerkar/AI Agents/twitteragent/twitterenv/lib/python3.10/site-packages/httpcore/_sync/connection_pool.py", line 237, in handle_request
    response = connection.handle_request(request)
  File "/Users/sanchaythalnerkar/AI Agents/twitteragent/twitterenv/lib/python3.10/site-packages/httpcore/_sync/connection.py", line 86, in handle_request
    raise exc
  File "/Users/sanchaythalnerkar/AI Agents/twitteragent/twitterenv/lib/python3.10/site-packages/httpcore/_sync/connection.py", line 63, in handle_request
    stream = self._connect(request)
  File "/Users/sanchaythalnerkar/AI Agents/twitteragent/twitterenv/lib/python3.10/site-packages/httpcore/_sync/connection.py", line 111, in _connect
    stream = self._network_backend.connect_tcp(**kwargs)
  File "/Users/sanchaythalnerkar/AI Agents/twitteragent/twitterenv/lib/python3.10/site-packages/httpcore/backends/sync.py", line 85, in connect_tcp
    with map_exceptions(exc_map):
  File "/opt/homebrew/Cellar/python@3.10/3.10.14_1/Frameworks/Python.framework/Versions/3.10/lib/python3.10/contextlib.py", line 153, in __exit__
    self.gen.throw(typ, value, traceback)
  File "/Users/sanchaythalnerkar/AI Agents/twitteragent/twitterenv/lib/python3.10/site-packages/httpcore/_exceptions.py", line 12, in map_exceptions
    raise to_exc(exc)
httpcore.ConnectError: [Errno 8] nodename nor servname provided, or not known

The above exception was the direct cause of the following exception:

Traceback (most recent call last):
  File "/Users/sanchaythalnerkar/AI Agents/twitteragent/twitterenv/lib/python3.10/site-packages/openai/_base_client.py", line 973, in _request
    response = self._client.send(
  File "/Users/sanchaythalnerkar/AI Agents/twitteragent/twitterenv/lib/python3.10/site-packages/httpx/_client.py", line 902, in send
    response = self._send_handling_auth(
  File "/Users/sanchaythalnerkar/AI Agents/twitteragent/twitterenv/lib/python3.10/site-packages/httpx/_client.py", line 930, in _send_handling_auth
    response = self._send_handling_redirects(
  File "/Users/sanchaythalnerkar/AI Agents/twitteragent/twitterenv/lib/python3.10/site-packages/httpx/_client.py", line 967, in _send_handling_redirects
    response = self._send_single_request(request)
  File "/Users/sanchaythalnerkar/AI Agents/twitteragent/twitterenv/lib/python3.10/site-packages/httpx/_client.py", line 1003, in _send_single_request
    response = transport.handle_request(request)
  File "/Users/sanchaythalnerkar/AI Agents/twitteragent/twitterenv/lib/python3.10/site-packages/httpx/_transports/default.py", line 217, in handle_request
    with map_httpcore_exceptions():
  File "/opt/homebrew/Cellar/python@3.10/3.10.14_1/Frameworks/Python.framework/Versions/3.10/lib/python3.10/contextlib.py", line 153, in __exit__
    self.gen.throw(typ, value, traceback)
  File "/Users/sanchaythalnerkar/AI Agents/twitteragent/twitterenv/lib/python3.10/site-packages/httpx/_transports/default.py", line 77, in map_httpcore_exceptions
    raise mapped_exc(message) from exc
httpx.ConnectError: [Errno 8] nodename nor servname provided, or not known

During handling of the above exception, another exception occurred:

Traceback (most recent call last):
  File "/Users/sanchaythalnerkar/AI Agents/twitteragent/twitterenv/lib/python3.10/site-packages/httpcore/_exceptions.py", line 8, in map_exceptions
    yield
  File "/Users/sanchaythalnerkar/AI Agents/twitteragent/twitterenv/lib/python3.10/site-packages/httpcore/backends/sync.py", line 86, in connect_tcp
    sock = socket.create_connection(
  File "/opt/homebrew/Cellar/python@3.10/3.10.14_1/Frameworks/Python.framework/Versions/3.10/lib/python3.10/socket.py", line 824, in create_connection
    for res in getaddrinfo(host, port, 0, SOCK_STREAM):
  File "/opt/homebrew/Cellar/python@3.10/3.10.14_1/Frameworks/Python.framework/Versions/3.10/lib/python3.10/socket.py", line 955, in getaddrinfo
    for res in _socket.getaddrinfo(host, port, family, type, proto, flags):
socket.gaierror: [Errno 8] nodename nor servname provided, or not known

During handling of the above exception, another exception occurred:

Traceback (most recent call last):
  File "/Users/sanchaythalnerkar/AI Agents/twitteragent/twitterenv/lib/python3.10/site-packages/httpx/_transports/default.py", line 60, in map_httpcore_exceptions
    yield
  File "/Users/sanchaythalnerkar/AI Agents/twitteragent/twitterenv/lib/python3.10/site-packages/httpx/_transports/default.py", line 218, in handle_request
    resp = self._pool.handle_request(req)
  File "/Users/sanchaythalnerkar/AI Agents/twitteragent/twitterenv/lib/python3.10/site-packages/httpcore/_sync/connection_pool.py", line 253, in handle_request
    raise exc
  File "/Users/sanchaythalnerkar/AI Agents/twitteragent/twitterenv/lib/python3.10/site-packages/httpcore/_sync/connection_pool.py", line 237, in handle_request
    response = connection.handle_request(request)
  File "/Users/sanchaythalnerkar/AI Agents/twitteragent/twitterenv/lib/python3.10/site-packages/httpcore/_sync/connection.py", line 86, in handle_request
    raise exc
  File "/Users/sanchaythalnerkar/AI Agents/twitteragent/twitterenv/lib/python3.10/site-packages/httpcore/_sync/connection.py", line 63, in handle_request
    stream = self._connect(request)
  File "/Users/sanchaythalnerkar/AI Agents/twitteragent/twitterenv/lib/python3.10/site-packages/httpcore/_sync/connection.py", line 111, in _connect
    stream = self._network_backend.connect_tcp(**kwargs)
  File "/Users/sanchaythalnerkar/AI Agents/twitteragent/twitterenv/lib/python3.10/site-packages/httpcore/backends/sync.py", line 85, in connect_tcp
    with map_exceptions(exc_map):
  File "/opt/homebrew/Cellar/python@3.10/3.10.14_1/Frameworks/Python.framework/Versions/3.10/lib/python3.10/contextlib.py", line 153, in __exit__
    self.gen.throw(typ, value, traceback)
  File "/Users/sanchaythalnerkar/AI Agents/twitteragent/twitterenv/lib/python3.10/site-packages/httpcore/_exceptions.py", line 12, in map_exceptions
    raise to_exc(exc)
httpcore.ConnectError: [Errno 8] nodename nor servname provided, or not known

The above exception was the direct cause of the following exception:

Traceback (most recent call last):
  File "/Users/sanchaythalnerkar/AI Agents/twitteragent/twitterenv/lib/python3.10/site-packages/openai/_base_client.py", line 973, in _request
    response = self._client.send(
  File "/Users/sanchaythalnerkar/AI Agents/twitteragent/twitterenv/lib/python3.10/site-packages/httpx/_client.py", line 902, in send
    response = self._send_handling_auth(
  File "/Users/sanchaythalnerkar/AI Agents/twitteragent/twitterenv/lib/python3.10/site-packages/httpx/_client.py", line 930, in _send_handling_auth
    response = self._send_handling_redirects(
  File "/Users/sanchaythalnerkar/AI Agents/twitteragent/twitterenv/lib/python3.10/site-packages/httpx/_client.py", line 967, in _send_handling_redirects
    response = self._send_single_request(request)
  File "/Users/sanchaythalnerkar/AI Agents/twitteragent/twitterenv/lib/python3.10/site-packages/httpx/_client.py", line 1003, in _send_single_request
    response = transport.handle_request(request)
  File "/Users/sanchaythalnerkar/AI Agents/twitteragent/twitterenv/lib/python3.10/site-packages/httpx/_transports/default.py", line 217, in handle_request
    with map_httpcore_exceptions():
  File "/opt/homebrew/Cellar/python@3.10/3.10.14_1/Frameworks/Python.framework/Versions/3.10/lib/python3.10/contextlib.py", line 153, in __exit__
    self.gen.throw(typ, value, traceback)
  File "/Users/sanchaythalnerkar/AI Agents/twitteragent/twitterenv/lib/python3.10/site-packages/httpx/_transports/default.py", line 77, in map_httpcore_exceptions
    raise mapped_exc(message) from exc
httpx.ConnectError: [Errno 8] nodename nor servname provided, or not known

During handling of the above exception, another exception occurred:

Traceback (most recent call last):
  File "/Users/sanchaythalnerkar/AI Agents/twitteragent/twitterenv/lib/python3.10/site-packages/httpcore/_exceptions.py", line 8, in map_exceptions
    yield
  File "/Users/sanchaythalnerkar/AI Agents/twitteragent/twitterenv/lib/python3.10/site-packages/httpcore/backends/sync.py", line 86, in connect_tcp
    sock = socket.create_connection(
  File "/opt/homebrew/Cellar/python@3.10/3.10.14_1/Frameworks/Python.framework/Versions/3.10/lib/python3.10/socket.py", line 824, in create_connection
    for res in getaddrinfo(host, port, 0, SOCK_STREAM):
  File "/opt/homebrew/Cellar/python@3.10/3.10.14_1/Frameworks/Python.framework/Versions/3.10/lib/python3.10/socket.py", line 955, in getaddrinfo
    for res in _socket.getaddrinfo(host, port, family, type, proto, flags):
socket.gaierror: [Errno 8] nodename nor servname provided, or not known

During handling of the above exception, another exception occurred:

Traceback (most recent call last):
  File "/Users/sanchaythalnerkar/AI Agents/twitteragent/twitterenv/lib/python3.10/site-packages/httpx/_transports/default.py", line 60, in map_httpcore_exceptions
    yield
  File "/Users/sanchaythalnerkar/AI Agents/twitteragent/twitterenv/lib/python3.10/site-packages/httpx/_transports/default.py", line 218, in handle_request
    resp = self._pool.handle_request(req)
  File "/Users/sanchaythalnerkar/AI Agents/twitteragent/twitterenv/lib/python3.10/site-packages/httpcore/_sync/connection_pool.py", line 253, in handle_request
    raise exc
  File "/Users/sanchaythalnerkar/AI Agents/twitteragent/twitterenv/lib/python3.10/site-packages/httpcore/_sync/connection_pool.py", line 237, in handle_request
    response = connection.handle_request(request)
  File "/Users/sanchaythalnerkar/AI Agents/twitteragent/twitterenv/lib/python3.10/site-packages/httpcore/_sync/connection.py", line 86, in handle_request
    raise exc
  File "/Users/sanchaythalnerkar/AI Agents/twitteragent/twitterenv/lib/python3.10/site-packages/httpcore/_sync/connection.py", line 63, in handle_request
    stream = self._connect(request)
  File "/Users/sanchaythalnerkar/AI Agents/twitteragent/twitterenv/lib/python3.10/site-packages/httpcore/_sync/connection.py", line 111, in _connect
    stream = self._network_backend.connect_tcp(**kwargs)
  File "/Users/sanchaythalnerkar/AI Agents/twitteragent/twitterenv/lib/python3.10/site-packages/httpcore/backends/sync.py", line 85, in connect_tcp
    with map_exceptions(exc_map):
  File "/opt/homebrew/Cellar/python@3.10/3.10.14_1/Frameworks/Python.framework/Versions/3.10/lib/python3.10/contextlib.py", line 153, in __exit__
    self.gen.throw(typ, value, traceback)
  File "/Users/sanchaythalnerkar/AI Agents/twitteragent/twitterenv/lib/python3.10/site-packages/httpcore/_exceptions.py", line 12, in map_exceptions
    raise to_exc(exc)
httpcore.ConnectError: [Errno 8] nodename nor servname provided, or not known

The above exception was the direct cause of the following exception:

Traceback (most recent call last):
  File "/Users/sanchaythalnerkar/AI Agents/twitteragent/twitterenv/lib/python3.10/site-packages/openai/_base_client.py", line 973, in _request
    response = self._client.send(
  File "/Users/sanchaythalnerkar/AI Agents/twitteragent/twitterenv/lib/python3.10/site-packages/httpx/_client.py", line 902, in send
    response = self._send_handling_auth(
  File "/Users/sanchaythalnerkar/AI Agents/twitteragent/twitterenv/lib/python3.10/site-packages/httpx/_client.py", line 930, in _send_handling_auth
    response = self._send_handling_redirects(
  File "/Users/sanchaythalnerkar/AI Agents/twitteragent/twitterenv/lib/python3.10/site-packages/httpx/_client.py", line 967, in _send_handling_redirects
    response = self._send_single_request(request)
  File "/Users/sanchaythalnerkar/AI Agents/twitteragent/twitterenv/lib/python3.10/site-packages/httpx/_client.py", line 1003, in _send_single_request
    response = transport.handle_request(request)
  File "/Users/sanchaythalnerkar/AI Agents/twitteragent/twitterenv/lib/python3.10/site-packages/httpx/_transports/default.py", line 217, in handle_request
    with map_httpcore_exceptions():
  File "/opt/homebrew/Cellar/python@3.10/3.10.14_1/Frameworks/Python.framework/Versions/3.10/lib/python3.10/contextlib.py", line 153, in __exit__
    self.gen.throw(typ, value, traceback)
  File "/Users/sanchaythalnerkar/AI Agents/twitteragent/twitterenv/lib/python3.10/site-packages/httpx/_transports/default.py", line 77, in map_httpcore_exceptions
    raise mapped_exc(message) from exc
httpx.ConnectError: [Errno 8] nodename nor servname provided, or not known

The above exception was the direct cause of the following exception:

Traceback (most recent call last):
  File "/Users/sanchaythalnerkar/AI Agents/twitteragent/main.py", line 24, in tweet_loop
    tweet_content = generate_tweet_content()
  File "/Users/sanchaythalnerkar/AI Agents/twitteragent/twitter_utils.py", line 140, in generate_tweet_content
    response = client.chat.completions.create(
  File "/Users/sanchaythalnerkar/AI Agents/twitteragent/twitterenv/lib/python3.10/site-packages/openai/_utils/_utils.py", line 274, in wrapper
    return func(*args, **kwargs)
  File "/Users/sanchaythalnerkar/AI Agents/twitteragent/twitterenv/lib/python3.10/site-packages/openai/resources/chat/completions.py", line 668, in create
    return self._post(
  File "/Users/sanchaythalnerkar/AI Agents/twitteragent/twitterenv/lib/python3.10/site-packages/openai/_base_client.py", line 1260, in post
    return cast(ResponseT, self.request(cast_to, opts, stream=stream, stream_cls=stream_cls))
  File "/Users/sanchaythalnerkar/AI Agents/twitteragent/twitterenv/lib/python3.10/site-packages/openai/_base_client.py", line 937, in request
    return self._request(
  File "/Users/sanchaythalnerkar/AI Agents/twitteragent/twitterenv/lib/python3.10/site-packages/openai/_base_client.py", line 997, in _request
    return self._retry_request(
  File "/Users/sanchaythalnerkar/AI Agents/twitteragent/twitterenv/lib/python3.10/site-packages/openai/_base_client.py", line 1075, in _retry_request
    return self._request(
  File "/Users/sanchaythalnerkar/AI Agents/twitteragent/twitterenv/lib/python3.10/site-packages/openai/_base_client.py", line 997, in _request
    return self._retry_request(
  File "/Users/sanchaythalnerkar/AI Agents/twitteragent/twitterenv/lib/python3.10/site-packages/openai/_base_client.py", line 1075, in _retry_request
    return self._request(
  File "/Users/sanchaythalnerkar/AI Agents/twitteragent/twitterenv/lib/python3.10/site-packages/openai/_base_client.py", line 1007, in _request
    raise APIConnectionError(request=request) from err
openai.APIConnectionError: Connection error.
2024-09-01 18:31:26 - Waiting for 10.75 minutes before next check
2024-09-01 18:42:11 - Skipped tweeting this interval
2024-09-01 18:42:11 - Waiting for 12.45 minutes before next check
2024-09-01 18:54:38 - Skipped tweeting this interval
2024-09-01 18:54:38 - Waiting for 10.23 minutes before next check
2024-09-01 19:04:53 - Generated tweet:
ethical ai shapes a fairer society—prioritize transparency and accountability in every model.
2024-09-01 19:04:53 - Character count: 93
2024-09-01 19:04:53 - Line count: 1
2024-09-01 19:04:54 - Twitter API response: {
    "data": {
        "edit_history_tweet_ids": [
            "1830237900476498392"
        ],
        "id": "1830237900476498392",
        "text": "ethical ai shapes a fairer society\u2014prioritize transparency and accountability in every model."
    }
}
2024-09-01 19:04:54 - Waiting for 15.65 minutes before next check
2024-09-01 19:20:35 - Generated tweet:
embrace discomfort; it's the catalyst for real personal growth. seek it out, don't avoid it.
2024-09-01 19:20:35 - Character count: 92
2024-09-01 19:20:35 - Line count: 1
2024-09-01 19:20:35 - Twitter API response: {
    "data": {
        "edit_history_tweet_ids": [
            "1830241848356401505"
        ],
        "id": "1830241848356401505",
        "text": "embrace discomfort; it's the catalyst for real personal growth. seek it out, don't avoid it."
    }
}
2024-09-01 19:20:35 - Waiting for 13.72 minutes before next check
2024-09-01 19:34:19 - Generated tweet:
automl reduces the barrier to entry for ai, making advanced models accessible to everyone.
2024-09-01 19:34:19 - Character count: 90
2024-09-01 19:34:19 - Line count: 1
2024-09-01 19:34:20 - Twitter API response: {
    "data": {
        "edit_history_tweet_ids": [
            "1830245306384224437"
        ],
        "id": "1830245306384224437",
        "text": "automl reduces the barrier to entry for ai, making advanced models accessible to everyone."
    }
}
2024-09-01 19:34:20 - Waiting for 10.50 minutes before next check
2024-09-01 19:44:50 - Generated tweet:
ai ethics isn't optional; it's foundational. responsible ai shapes a just society.
2024-09-01 19:44:50 - Character count: 82
2024-09-01 19:44:50 - Line count: 1
2024-09-01 19:44:51 - Twitter API response: {
    "data": {
        "edit_history_tweet_ids": [
            "1830247954575446304"
        ],
        "id": "1830247954575446304",
        "text": "ai ethics isn't optional; it's foundational. responsible ai shapes a just society."
    }
}
2024-09-01 19:44:51 - Waiting for 19.75 minutes before next check
2024-09-01 20:04:37 - Generated tweet:
constant learning is the only way to stay relevant in the ever-evolving tech industry.
2024-09-01 20:04:37 - Character count: 86
2024-09-01 20:04:37 - Line count: 1
2024-09-01 20:04:38 - Twitter API response: {
    "data": {
        "edit_history_tweet_ids": [
            "1830252931536285778"
        ],
        "id": "1830252931536285778",
        "text": "constant learning is the only way to stay relevant in the ever-evolving tech industry."
    }
}
2024-09-01 20:04:38 - Waiting for 19.80 minutes before next check
2024-09-01 20:24:26 - Generated tweet:
ai ethics isn't just a guideline; it's the foundation for trust in our future tech.
2024-09-01 20:24:26 - Character count: 83
2024-09-01 20:24:26 - Line count: 1
2024-09-01 20:24:27 - Twitter API response: {
    "data": {
        "edit_history_tweet_ids": [
            "1830257920464068929"
        ],
        "id": "1830257920464068929",
        "text": "ai ethics isn't just a guideline; it's the foundation for trust in our future tech."
    }
}
2024-09-01 20:24:27 - Waiting for 18.20 minutes before next check
2024-09-01 20:43:00 - Generated tweet:
transfer learning cuts training time and enhances performance in resource-constrained projects.
2024-09-01 20:43:00 - Character count: 95
2024-09-01 20:43:00 - Line count: 1
2024-09-01 20:43:01 - Twitter API response: {
    "data": {
        "edit_history_tweet_ids": [
            "1830262591316439226"
        ],
        "id": "1830262591316439226",
        "text": "transfer learning cuts training time and enhances performance in resource-constrained projects."
    }
}
2024-09-01 20:43:01 - Waiting for 13.27 minutes before next check
2024-09-01 21:03:47 - Generated tweet:
graph neural networks unlock hidden patterns in data, connecting the dots like never before.
2024-09-01 21:03:47 - Character count: 92
2024-09-01 21:03:47 - Line count: 1
2024-09-01 21:03:48 - Twitter API response: {
    "data": {
        "edit_history_tweet_ids": [
            "1830267823500718571"
        ],
        "id": "1830267823500718571",
        "text": "graph neural networks unlock hidden patterns in data, connecting the dots like never before."
    }
}
2024-09-01 21:03:48 - Waiting for 16.23 minutes before next check
2024-09-01 21:49:01 - Generated tweet:
AI must prioritize human values over efficiency to ensure ethical progress.
2024-09-01 21:49:01 - Character count: 75
2024-09-01 21:49:01 - Line count: 1
2024-09-01 21:49:02 - Twitter API response: {
    "data": {
        "edit_history_tweet_ids": [
            "1830279206288413159"
        ],
        "id": "1830279206288413159",
        "text": "AI must prioritize human values over efficiency to ensure ethical progress."
    }
}
2024-09-01 21:49:02 - Waiting for 19.15 minutes before next check
2024-09-01 22:08:12 - Generated tweet:
generative ai turns data into art; the key is mastering the balance between creativity and control.
2024-09-01 22:08:12 - Character count: 99
2024-09-01 22:08:12 - Line count: 1
2024-09-01 22:08:12 - Twitter API response: {
    "data": {
        "edit_history_tweet_ids": [
            "1830284031763882378"
        ],
        "id": "1830284031763882378",
        "text": "generative ai turns data into art; the key is mastering the balance between creativity and control."
    }
}
2024-09-01 22:08:12 - Waiting for 13.67 minutes before next check
2024-09-01 22:21:53 - Generated tweet:
autoML is revolutionizing AI by democratizing model building. anyone can now create robust models.
2024-09-01 22:21:53 - Character count: 98
2024-09-01 22:21:53 - Line count: 1
2024-09-01 22:21:54 - Twitter API response: {
    "data": {
        "edit_history_tweet_ids": [
            "1830287477166268420"
        ],
        "id": "1830287477166268420",
        "text": "autoML is revolutionizing AI by democratizing model building. anyone can now create robust models."
    }
}
2024-09-01 22:21:54 - Waiting for 17.82 minutes before next check
2024-09-01 22:39:44 - Generated tweet:
prioritize tasks by impact, not urgency. time spent on what matters most is time well invested.
2024-09-01 22:39:44 - Character count: 95
2024-09-01 22:39:44 - Line count: 1
2024-09-01 22:39:44 - Twitter API response: {
    "data": {
        "edit_history_tweet_ids": [
            "1830291967001157896"
        ],
        "id": "1830291967001157896",
        "text": "prioritize tasks by impact, not urgency. time spent on what matters most is time well invested."
    }
}
2024-09-01 22:39:44 - Waiting for 19.47 minutes before next check
2024-09-01 23:07:23 - Generated tweet:
reuse pre-trained models to drastically cut down training time and improve accuracy. #AI
2024-09-01 23:07:23 - Character count: 88
2024-09-01 23:07:23 - Line count: 1
2024-09-01 23:07:24 - Twitter API response: {
    "data": {
        "edit_history_tweet_ids": [
            "1830298928618909725"
        ],
        "id": "1830298928618909725",
        "text": "reuse pre-trained models to drastically cut down training time and improve accuracy. #AI"
    }
}
2024-09-01 23:07:24 - Waiting for 10.78 minutes before next check
2024-09-01 23:18:12 - Generated tweet:
graph neural networks excel at capturing relationships in complex, interconnected data.
2024-09-01 23:18:12 - Character count: 87
2024-09-01 23:18:12 - Line count: 1
2024-09-01 23:18:13 - Twitter API response: {
    "data": {
        "edit_history_tweet_ids": [
            "1830301647932629458"
        ],
        "id": "1830301647932629458",
        "text": "graph neural networks excel at capturing relationships in complex, interconnected data."
    }
}
2024-09-01 23:18:13 - Waiting for 16.15 minutes before next check
2024-09-01 23:39:47 - Generated tweet:
time series forecasting improves with simplicity; focus on linear models before diving into complexity.
2024-09-01 23:39:47 - Character count: 103
2024-09-01 23:39:47 - Line count: 1
2024-09-01 23:39:47 - Twitter API response: {
    "data": {
        "edit_history_tweet_ids": [
            "1830307078969458835"
        ],
        "id": "1830307078969458835",
        "text": "time series forecasting improves with simplicity; focus on linear models before diving into complexity."
    }
}
2024-09-01 23:39:47 - Waiting for 11.90 minutes before next check
2024-09-01 23:51:42 - Generated tweet:
edge ai in iot means smarter, faster decisions right at the source. revolutionizing real-time.
2024-09-01 23:51:42 - Character count: 94
2024-09-01 23:51:42 - Line count: 1
2024-09-01 23:51:43 - Twitter API response: {
    "data": {
        "edit_history_tweet_ids": [
            "1830310080191004896"
        ],
        "id": "1830310080191004896",
        "text": "edge ai in iot means smarter, faster decisions right at the source. revolutionizing real-time."
    }
}
2024-09-01 23:51:43 - Waiting for 12.67 minutes before next check
2024-09-02 00:04:24 - Generated tweet:
real-world impact of computer vision: beyond recognition, towards understanding context.
2024-09-02 00:04:24 - Character count: 88
2024-09-02 00:04:24 - Line count: 1
2024-09-02 00:04:25 - Twitter API response: {
    "data": {
        "edit_history_tweet_ids": [
            "1830313274769854794"
        ],
        "id": "1830313274769854794",
        "text": "real-world impact of computer vision: beyond recognition, towards understanding context."
    }
}
2024-09-02 00:04:25 - Waiting for 10.98 minutes before next check
2024-09-02 00:15:24 - Skipped tweeting this interval
2024-09-02 00:15:24 - Waiting for 16.30 minutes before next check
2024-09-02 00:31:42 - Skipped tweeting this interval
2024-09-02 00:31:42 - Waiting for 11.15 minutes before next check
2024-09-02 00:42:51 - Skipped tweeting this interval
2024-09-02 00:42:51 - Waiting for 10.67 minutes before next check
2024-09-02 00:53:31 - Generated tweet:
graph neural networks excel at capturing relationships in data. think connections, not just nodes.
2024-09-02 00:53:31 - Character count: 98
2024-09-02 00:53:31 - Line count: 1
2024-09-02 00:53:32 - Twitter API response: {
    "data": {
        "edit_history_tweet_ids": [
            "1830325637388922882"
        ],
        "id": "1830325637388922882",
        "text": "graph neural networks excel at capturing relationships in data. think connections, not just nodes."
    }
}
2024-09-02 00:53:32 - Waiting for 15.43 minutes before next check
2024-09-02 01:08:59 - Generated tweet:
clean data is the foundation of accurate AI models; preprocess thoroughly for success.
2024-09-02 01:08:59 - Character count: 86
2024-09-02 01:08:59 - Line count: 1
2024-09-02 01:09:00 - Twitter API response: {
    "data": {
        "edit_history_tweet_ids": [
            "1830329527274537195"
        ],
        "id": "1830329527274537195",
        "text": "clean data is the foundation of accurate AI models; preprocess thoroughly for success."
    }
}
2024-09-02 01:09:00 - Waiting for 18.72 minutes before next check
2024-09-02 01:27:43 - Generated tweet:
federated learning is redefining data privacy, enabling smarter models without data exposure.
2024-09-02 01:27:43 - Character count: 93
2024-09-02 01:27:43 - Line count: 1
2024-09-02 01:27:44 - Twitter API response: {
    "data": {
        "edit_history_tweet_ids": [
            "1830334243907719611"
        ],
        "id": "1830334243907719611",
        "text": "federated learning is redefining data privacy, enabling smarter models without data exposure."
    }
}
2024-09-02 01:27:44 - Waiting for 18.53 minutes before next check
2024-09-02 02:37:21 - Skipped tweeting this interval
2024-09-02 02:37:21 - Waiting for 19.32 minutes before next check
2024-09-02 10:10:52 - Twitter bot stopped
2024-09-02 10:10:54 - Twitter bot started
2024-09-02 10:10:58 - Generated tweet:
interpretability in AI models isn't optional; it's essential for trust and accountability.
2024-09-02 10:10:58 - Character count: 90
2024-09-02 10:10:58 - Line count: 1
2024-09-02 10:10:59 - Twitter API response: {
    "data": {
        "edit_history_tweet_ids": [
            "1830465921522995509"
        ],
        "id": "1830465921522995509",
        "text": "interpretability in AI models isn't optional; it's essential for trust and accountability."
    }
}
2024-09-02 10:10:59 - Waiting for 17.20 minutes before next check
2024-09-02 10:28:11 - Generated tweet:
growth happens outside comfort zones; challenge yourself to evolve consistently.
2024-09-02 10:28:11 - Character count: 80
2024-09-02 10:28:11 - Line count: 1
2024-09-02 10:28:12 - Twitter API response: {
    "data": {
        "edit_history_tweet_ids": [
            "1830470256847949937"
        ],
        "id": "1830470256847949937",
        "text": "growth happens outside comfort zones; challenge yourself to evolve consistently."
    }
}
2024-09-02 10:28:12 - Waiting for 15.05 minutes before next check
2024-09-02 10:56:14 - Generated tweet:
ethical AI isn't just about tech; it's about ensuring society reaps the benefits fairly.
2024-09-02 10:56:14 - Character count: 88
2024-09-02 10:56:14 - Line count: 1
2024-09-02 10:56:15 - Twitter API response: {
    "data": {
        "edit_history_tweet_ids": [
            "1830477314980798918"
        ],
        "id": "1830477314980798918",
        "text": "ethical AI isn't just about tech; it's about ensuring society reaps the benefits fairly."
    }
}
2024-09-02 10:56:15 - Waiting for 14.63 minutes before next check
2024-09-02 11:10:57 - Generated tweet:
generative ai techniques unlock creativity by turning data into unique, actionable insights.
2024-09-02 11:10:57 - Character count: 92
2024-09-02 11:10:57 - Line count: 1
2024-09-02 11:10:57 - Twitter API response: {
    "data": {
        "edit_history_tweet_ids": [
            "1830481015636107581"
        ],
        "id": "1830481015636107581",
        "text": "generative ai techniques unlock creativity by turning data into unique, actionable insights."
    }
}
2024-09-02 11:10:57 - Waiting for 18.43 minutes before next check
2024-09-02 11:29:27 - Generated tweet:
robotics and ai integration is redefining efficiency; the future is autonomous and intelligent.
2024-09-02 11:29:27 - Character count: 95
2024-09-02 11:29:27 - Line count: 1
2024-09-02 11:29:31 - Twitter API response: {
    "data": {
        "edit_history_tweet_ids": [
            "1830485686568305142"
        ],
        "id": "1830485686568305142",
        "text": "robotics and ai integration is redefining efficiency; the future is autonomous and intelligent."
    }
}
2024-09-02 11:29:31 - Waiting for 12.78 minutes before next check
2024-09-02 11:42:19 - Generated tweet:
ai accelerates scientific discovery by analyzing vast datasets faster than any human could.
2024-09-02 11:42:19 - Character count: 91
2024-09-02 11:42:19 - Line count: 1
2024-09-02 11:42:19 - Twitter API response: {
    "data": {
        "edit_history_tweet_ids": [
            "1830488910150893730"
        ],
        "id": "1830488910150893730",
        "text": "ai accelerates scientific discovery by analyzing vast datasets faster than any human could."
    }
}
2024-09-02 11:42:19 - Waiting for 14.92 minutes before next check
2024-09-02 11:57:16 - Generated tweet:
growth happens when you step out of comfort, embrace uncertainty, and keep moving forward.
2024-09-02 11:57:16 - Character count: 90
2024-09-02 11:57:16 - Line count: 1
2024-09-02 11:57:17 - Twitter API response: {
    "data": {
        "edit_history_tweet_ids": [
            "1830492673150492879"
        ],
        "id": "1830492673150492879",
        "text": "growth happens when you step out of comfort, embrace uncertainty, and keep moving forward."
    }
}
2024-09-02 11:57:17 - Waiting for 17.63 minutes before next check
2024-09-02 12:14:58 - Generated tweet:
reinforcement learning is proving that trial and error isn't just for humans—it's for machines too.
2024-09-02 12:14:58 - Character count: 99
2024-09-02 12:14:58 - Line count: 1
2024-09-02 12:14:59 - Twitter API response: {
    "data": {
        "edit_history_tweet_ids": [
            "1830497130139517236"
        ],
        "id": "1830497130139517236",
        "text": "reinforcement learning is proving that trial and error isn't just for humans\u2014it's for machines too."
    }
}
2024-09-02 12:14:59 - Waiting for 13.18 minutes before next check
2024-09-02 12:28:11 - Generated tweet:
ai's evolution in real-time data processing is transforming predictive analytics.
2024-09-02 12:28:11 - Character count: 81
2024-09-02 12:28:11 - Line count: 1
2024-09-02 12:28:12 - Twitter API response: {
    "data": {
        "edit_history_tweet_ids": [
            "1830500454389764385"
        ],
        "id": "1830500454389764385",
        "text": "ai's evolution in real-time data processing is transforming predictive analytics."
    }
}
2024-09-02 12:28:12 - Waiting for 17.78 minutes before next check
2024-09-02 12:32:17 - Twitter bot stopped
2024-09-02 12:32:20 - Twitter bot started
2024-09-02 12:32:21 - Generated tweet:
seasonality and trend are key to accurate time series forecasting. model them well.
2024-09-02 12:32:21 - Character count: 83
2024-09-02 12:32:21 - Line count: 1
2024-09-02 12:32:22 - Twitter API response: {
    "data": {
        "edit_history_tweet_ids": [
            "1830501503523541219"
        ],
        "id": "1830501503523541219",
        "text": "seasonality and trend are key to accurate time series forecasting. model them well."
    }
}
2024-09-02 12:32:22 - Waiting for 17.48 minutes before next check
2024-09-02 12:49:55 - Generated tweet:
graph neural networks excel in understanding relationships in complex data structures.
2024-09-02 12:49:55 - Character count: 86
2024-09-02 12:49:55 - Line count: 1
2024-09-02 12:49:55 - Twitter API response: {
    "data": {
        "edit_history_tweet_ids": [
            "1830505922499588259"
        ],
        "id": "1830505922499588259",
        "text": "graph neural networks excel in understanding relationships in complex data structures."
    }
}
2024-09-02 12:49:55 - Waiting for 13.57 minutes before next check
2024-09-02 13:03:33 - Generated tweet:
edge ai in iot devices enables real-time data processing, reducing latency and boosting efficiency.
2024-09-02 13:03:33 - Character count: 99
2024-09-02 13:03:33 - Line count: 1
2024-09-02 13:03:34 - Twitter API response: {
    "data": {
        "edit_history_tweet_ids": [
            "1830509355789131946"
        ],
        "id": "1830509355789131946",
        "text": "edge ai in iot devices enables real-time data processing, reducing latency and boosting efficiency."
    }
}
2024-09-02 13:03:34 - Waiting for 17.37 minutes before next check
2024-09-02 13:20:57 - Generated tweet:
transformers revolutionize NLP by understanding context in ways traditional models can't.
2024-09-02 13:20:57 - Character count: 89
2024-09-02 13:20:57 - Line count: 1
2024-09-02 13:20:58 - Twitter API response: {
    "data": {
        "edit_history_tweet_ids": [
            "1830513732935385208"
        ],
        "id": "1830513732935385208",
        "text": "transformers revolutionize NLP by understanding context in ways traditional models can't."
    }
}
2024-09-02 13:20:58 - Waiting for 11.43 minutes before next check
2024-09-02 13:32:24 - Skipped tweeting this interval
2024-09-02 13:32:24 - Waiting for 12.38 minutes before next check
2024-09-02 13:44:48 - Generated tweet:
federated learning is the future of data privacy in AI, enabling smarter, decentralized growth.
2024-09-02 13:44:48 - Character count: 95
2024-09-02 13:44:48 - Line count: 1
2024-09-02 13:44:48 - Twitter API response: {
    "data": {
        "edit_history_tweet_ids": [
            "1830519733273157840"
        ],
        "id": "1830519733273157840",
        "text": "federated learning is the future of data privacy in AI, enabling smarter, decentralized growth."
    }
}
2024-09-02 13:44:48 - Waiting for 18.90 minutes before next check
2024-09-02 14:03:47 - Generated tweet:
machine learning can model climate patterns, unlocking new ways to combat climate change.
2024-09-02 14:03:47 - Character count: 89
2024-09-02 14:03:47 - Line count: 1
2024-09-02 14:03:47 - Twitter API response: {
    "data": {
        "edit_history_tweet_ids": [
            "1830524511021666621"
        ],
        "id": "1830524511021666621",
        "text": "machine learning can model climate patterns, unlocking new ways to combat climate change."
    }
}
2024-09-02 14:03:47 - Waiting for 12.52 minutes before next check
2024-09-02 15:10:39 - Skipped tweeting this interval
2024-09-02 15:10:39 - Waiting for 17.28 minutes before next check
2024-09-02 15:27:57 - Generated tweet:
even the smallest change in initial conditions can lead to vastly different outcomes. #entrepreneurial_lesson
2024-09-02 15:27:57 - Character count: 109
2024-09-02 15:27:57 - Line count: 1
2024-09-02 15:28:01 - Twitter API response: {
    "data": {
        "edit_history_tweet_ids": [
            "1830545708543283316"
        ],
        "id": "1830545708543283316",
        "text": "even the smallest change in initial conditions can lead to vastly different outcomes. #entrepreneurial_lesson"
    }
}
2024-09-02 15:28:01 - Waiting for 18.42 minutes before next check
2024-09-02 15:41:26 - Twitter bot stopped
2024-09-02 15:41:27 - Twitter bot started
2024-09-02 15:41:27 - An error occurred during the tweet process
Traceback (most recent call last):
  File "/Users/sanchaythalnerkar/AI Agents/twitteragent/main.py", line 24, in tweet_loop
    tweet_content = generate_tweet_content()
  File "/Users/sanchaythalnerkar/AI Agents/twitteragent/twitter_utils.py", line 141, in generate_tweet_content
    response = client.chat.completions.create(
  File "/Users/sanchaythalnerkar/AI Agents/twitteragent/twitterenv/lib/python3.10/site-packages/openai/_utils/_utils.py", line 274, in wrapper
    return func(*args, **kwargs)
  File "/Users/sanchaythalnerkar/AI Agents/twitteragent/twitterenv/lib/python3.10/site-packages/openai/resources/chat/completions.py", line 668, in create
    return self._post(
  File "/Users/sanchaythalnerkar/AI Agents/twitteragent/twitterenv/lib/python3.10/site-packages/openai/_base_client.py", line 1260, in post
    return cast(ResponseT, self.request(cast_to, opts, stream=stream, stream_cls=stream_cls))
  File "/Users/sanchaythalnerkar/AI Agents/twitteragent/twitterenv/lib/python3.10/site-packages/openai/_base_client.py", line 937, in request
    return self._request(
  File "/Users/sanchaythalnerkar/AI Agents/twitteragent/twitterenv/lib/python3.10/site-packages/openai/_base_client.py", line 1041, in _request
    raise self._make_status_error_from_response(err.response) from None
openai.AuthenticationError: Error code: 401 - {'error': {'message': 'Incorrect API key provided: sk-proj-************************************************************************************************************************EWQA. You can find your API key at https://platform.openai.com/account/api-keys.', 'type': 'invalid_request_error', 'param': None, 'code': 'invalid_api_key'}}
2024-09-02 15:41:27 - Waiting for 16.80 minutes before next check
2024-09-02 15:58:16 - An error occurred during the tweet process
Traceback (most recent call last):
  File "/Users/sanchaythalnerkar/AI Agents/twitteragent/main.py", line 24, in tweet_loop
    tweet_content = generate_tweet_content()
  File "/Users/sanchaythalnerkar/AI Agents/twitteragent/twitter_utils.py", line 141, in generate_tweet_content
    response = client.chat.completions.create(
  File "/Users/sanchaythalnerkar/AI Agents/twitteragent/twitterenv/lib/python3.10/site-packages/openai/_utils/_utils.py", line 274, in wrapper
    return func(*args, **kwargs)
  File "/Users/sanchaythalnerkar/AI Agents/twitteragent/twitterenv/lib/python3.10/site-packages/openai/resources/chat/completions.py", line 668, in create
    return self._post(
  File "/Users/sanchaythalnerkar/AI Agents/twitteragent/twitterenv/lib/python3.10/site-packages/openai/_base_client.py", line 1260, in post
    return cast(ResponseT, self.request(cast_to, opts, stream=stream, stream_cls=stream_cls))
  File "/Users/sanchaythalnerkar/AI Agents/twitteragent/twitterenv/lib/python3.10/site-packages/openai/_base_client.py", line 937, in request
    return self._request(
  File "/Users/sanchaythalnerkar/AI Agents/twitteragent/twitterenv/lib/python3.10/site-packages/openai/_base_client.py", line 1041, in _request
    raise self._make_status_error_from_response(err.response) from None
openai.AuthenticationError: Error code: 401 - {'error': {'message': 'Incorrect API key provided: sk-proj-************************************************************************************************************************EWQA. You can find your API key at https://platform.openai.com/account/api-keys.', 'type': 'invalid_request_error', 'param': None, 'code': 'invalid_api_key'}}
2024-09-02 15:58:16 - Waiting for 15.28 minutes before next check
2024-09-02 16:03:28 - Twitter bot stopped
2024-09-02 16:03:30 - Twitter bot started
2024-09-02 16:03:31 - Retrying request to /chat/completions in 0.787815 seconds
2024-09-02 16:03:32 - Retrying request to /chat/completions in 1.751669 seconds
2024-09-02 16:03:34 - An error occurred during the tweet process
Traceback (most recent call last):
  File "/Users/sanchaythalnerkar/AI Agents/twitteragent/main.py", line 24, in tweet_loop
    tweet_content = generate_tweet_content()
  File "/Users/sanchaythalnerkar/AI Agents/twitteragent/twitter_utils.py", line 141, in generate_tweet_content
    response = client.chat.completions.create(
  File "/Users/sanchaythalnerkar/AI Agents/twitteragent/twitterenv/lib/python3.10/site-packages/openai/_utils/_utils.py", line 274, in wrapper
    return func(*args, **kwargs)
  File "/Users/sanchaythalnerkar/AI Agents/twitteragent/twitterenv/lib/python3.10/site-packages/openai/resources/chat/completions.py", line 668, in create
    return self._post(
  File "/Users/sanchaythalnerkar/AI Agents/twitteragent/twitterenv/lib/python3.10/site-packages/openai/_base_client.py", line 1260, in post
    return cast(ResponseT, self.request(cast_to, opts, stream=stream, stream_cls=stream_cls))
  File "/Users/sanchaythalnerkar/AI Agents/twitteragent/twitterenv/lib/python3.10/site-packages/openai/_base_client.py", line 937, in request
    return self._request(
  File "/Users/sanchaythalnerkar/AI Agents/twitteragent/twitterenv/lib/python3.10/site-packages/openai/_base_client.py", line 1026, in _request
    return self._retry_request(
  File "/Users/sanchaythalnerkar/AI Agents/twitteragent/twitterenv/lib/python3.10/site-packages/openai/_base_client.py", line 1075, in _retry_request
    return self._request(
  File "/Users/sanchaythalnerkar/AI Agents/twitteragent/twitterenv/lib/python3.10/site-packages/openai/_base_client.py", line 1026, in _request
    return self._retry_request(
  File "/Users/sanchaythalnerkar/AI Agents/twitteragent/twitterenv/lib/python3.10/site-packages/openai/_base_client.py", line 1075, in _retry_request
    return self._request(
  File "/Users/sanchaythalnerkar/AI Agents/twitteragent/twitterenv/lib/python3.10/site-packages/openai/_base_client.py", line 1041, in _request
    raise self._make_status_error_from_response(err.response) from None
openai.RateLimitError: Error code: 429 - {'error': {'message': 'Your account is not active, please check your billing details on our website.', 'type': 'billing_not_active', 'param': None, 'code': 'billing_not_active'}}
2024-09-02 16:03:34 - Waiting for 14.85 minutes before next check
2024-09-02 16:18:26 - Retrying request to /chat/completions in 0.889211 seconds
2024-09-02 16:18:27 - Retrying request to /chat/completions in 1.865170 seconds
2024-09-02 16:18:29 - An error occurred during the tweet process
Traceback (most recent call last):
  File "/Users/sanchaythalnerkar/AI Agents/twitteragent/main.py", line 24, in tweet_loop
    tweet_content = generate_tweet_content()
  File "/Users/sanchaythalnerkar/AI Agents/twitteragent/twitter_utils.py", line 141, in generate_tweet_content
    response = client.chat.completions.create(
  File "/Users/sanchaythalnerkar/AI Agents/twitteragent/twitterenv/lib/python3.10/site-packages/openai/_utils/_utils.py", line 274, in wrapper
    return func(*args, **kwargs)
  File "/Users/sanchaythalnerkar/AI Agents/twitteragent/twitterenv/lib/python3.10/site-packages/openai/resources/chat/completions.py", line 668, in create
    return self._post(
  File "/Users/sanchaythalnerkar/AI Agents/twitteragent/twitterenv/lib/python3.10/site-packages/openai/_base_client.py", line 1260, in post
    return cast(ResponseT, self.request(cast_to, opts, stream=stream, stream_cls=stream_cls))
  File "/Users/sanchaythalnerkar/AI Agents/twitteragent/twitterenv/lib/python3.10/site-packages/openai/_base_client.py", line 937, in request
    return self._request(
  File "/Users/sanchaythalnerkar/AI Agents/twitteragent/twitterenv/lib/python3.10/site-packages/openai/_base_client.py", line 1026, in _request
    return self._retry_request(
  File "/Users/sanchaythalnerkar/AI Agents/twitteragent/twitterenv/lib/python3.10/site-packages/openai/_base_client.py", line 1075, in _retry_request
    return self._request(
  File "/Users/sanchaythalnerkar/AI Agents/twitteragent/twitterenv/lib/python3.10/site-packages/openai/_base_client.py", line 1026, in _request
    return self._retry_request(
  File "/Users/sanchaythalnerkar/AI Agents/twitteragent/twitterenv/lib/python3.10/site-packages/openai/_base_client.py", line 1075, in _retry_request
    return self._request(
  File "/Users/sanchaythalnerkar/AI Agents/twitteragent/twitterenv/lib/python3.10/site-packages/openai/_base_client.py", line 1041, in _request
    raise self._make_status_error_from_response(err.response) from None
openai.RateLimitError: Error code: 429 - {'error': {'message': 'Your account is not active, please check your billing details on our website.', 'type': 'billing_not_active', 'param': None, 'code': 'billing_not_active'}}
2024-09-02 16:18:29 - Waiting for 18.72 minutes before next check
2024-09-02 16:34:28 - Twitter bot stopped
2024-09-02 16:34:33 - Twitter bot started
2024-09-02 16:34:36 - Generated tweet:
fine-tuning entire models can be overkill, focus on adapting specific layers to new tasks for more efficient transfer learning
2024-09-02 16:34:36 - Character count: 126
2024-09-02 16:34:36 - Line count: 1
2024-09-02 16:34:36 - Twitter API response: {
    "data": {
        "edit_history_tweet_ids": [
            "1830562465152692470"
        ],
        "id": "1830562465152692470",
        "text": "fine-tuning entire models can be overkill, focus on adapting specific layers to new tasks for more efficient transfer learning"
    }
}
2024-09-02 16:34:36 - Waiting for 14.95 minutes before next check
2024-09-02 16:37:16 - Twitter bot stopped
2024-09-02 17:50:07 - Twitter bot started
2024-09-02 17:50:09 - HTTP Request: POST https://integrate.api.nvidia.com/v1/chat/completions "HTTP/1.1 200 OK"
2024-09-02 17:50:09 - Generated tweet:
adversarial ml reveals that even the most accurate ai models can be deceived by carefully crafted inputs, exposing vulnerabilities in AI decision-making.
2024-09-02 17:50:09 - Character count: 153
2024-09-02 17:50:09 - Line count: 1
2024-09-02 17:50:10 - Twitter API response: {
    "data": {
        "edit_history_tweet_ids": [
            "1830581481124598243"
        ],
        "id": "1830581481124598243",
        "text": "adversarial ml reveals that even the most accurate ai models can be deceived by carefully crafted inputs, exposing vulnerabilities in AI decision-making."
    }
}
2024-09-02 17:50:10 - Waiting for 15.42 minutes before next check
